2025-06-05 22:08:51.020 WARNING (SyncWorker_0) [annotatedyaml.constructors] YAML file /config/configuration.yaml contains duplicate key "host". Check lines 62 and 65
2025-06-05 22:08:51.020 WARNING (SyncWorker_0) [annotatedyaml.constructors] YAML file /config/configuration.yaml contains duplicate key "port". Check lines 63 and 66
2025-06-05 22:08:51.176 WARNING (SyncWorker_0) [homeassistant.loader] We found a custom integration hacs which has not been tested by Home Assistant. This component might cause stability problems, be sure to disable it if you experience issues with Home Assistant
2025-06-05 22:08:51.182 WARNING (SyncWorker_0) [homeassistant.loader] We found a custom integration faster_whisper_stt which has not been tested by Home Assistant. This component might cause stability problems, be sure to disable it if you experience issues with Home Assistant
2025-06-05 22:08:51.182 ERROR (SyncWorker_0) [homeassistant.loader] The custom integration 'faster_whisper_stt' does not have a version key in the manifest file and was blocked from loading. See https://developers.home-assistant.io/blog/2021/01/29/custom-integration-changes#versions for more details
2025-06-05 22:08:51.183 WARNING (SyncWorker_0) [homeassistant.loader] We found a custom integration openai_stt which has not been tested by Home Assistant. This component might cause stability problems, be sure to disable it if you experience issues with Home Assistant
2025-06-05 22:08:51.183 ERROR (SyncWorker_0) [homeassistant.loader] The custom integration 'openai_stt' does not have a version key in the manifest file and was blocked from loading. See https://developers.home-assistant.io/blog/2021/01/29/custom-integration-changes#versions for more details
2025-06-05 22:08:51.192 WARNING (SyncWorker_0) [homeassistant.loader] We found a custom integration google_home which has not been tested by Home Assistant. This component might cause stability problems, be sure to disable it if you experience issues with Home Assistant
2025-06-05 22:08:51.195 WARNING (SyncWorker_0) [homeassistant.loader] We found a custom integration browser_mod which has not been tested by Home Assistant. This component might cause stability problems, be sure to disable it if you experience issues with Home Assistant
2025-06-05 22:08:52.814 ERROR (Recorder) [homeassistant.components.recorder.core] Error during connection setup: (retrying in 3 seconds)
Traceback (most recent call last):
  File "/usr/local/lib/python3.13/site-packages/sqlalchemy/engine/base.py", line 146, in __init__
    self._dbapi_connection = engine.raw_connection()
                             ~~~~~~~~~~~~~~~~~~~~~^^
  File "/usr/local/lib/python3.13/site-packages/sqlalchemy/engine/base.py", line 3298, in raw_connection
    return self.pool.connect()
           ~~~~~~~~~~~~~~~~~^^
  File "/usr/local/lib/python3.13/site-packages/sqlalchemy/pool/base.py", line 449, in connect
    return _ConnectionFairy._checkout(self)
           ~~~~~~~~~~~~~~~~~~~~~~~~~~^^^^^^
  File "/usr/local/lib/python3.13/site-packages/sqlalchemy/pool/base.py", line 1264, in _checkout
    fairy = _ConnectionRecord.checkout(pool)
  File "/usr/local/lib/python3.13/site-packages/sqlalchemy/pool/base.py", line 713, in checkout
    rec = pool._do_get()
  File "/usr/local/lib/python3.13/site-packages/sqlalchemy/pool/impl.py", line 179, in _do_get
    with util.safe_reraise():
         ~~~~~~~~~~~~~~~~~^^
  File "/usr/local/lib/python3.13/site-packages/sqlalchemy/util/langhelpers.py", line 146, in __exit__
    raise exc_value.with_traceback(exc_tb)
  File "/usr/local/lib/python3.13/site-packages/sqlalchemy/pool/impl.py", line 177, in _do_get
    return self._create_connection()
           ~~~~~~~~~~~~~~~~~~~~~~~^^
  File "/usr/local/lib/python3.13/site-packages/sqlalchemy/pool/base.py", line 390, in _create_connection
    return _ConnectionRecord(self)
  File "/usr/local/lib/python3.13/site-packages/sqlalchemy/pool/base.py", line 675, in __init__
    self.__connect()
    ~~~~~~~~~~~~~~^^
  File "/usr/local/lib/python3.13/site-packages/sqlalchemy/pool/base.py", line 901, in __connect
    with util.safe_reraise():
         ~~~~~~~~~~~~~~~~~^^
  File "/usr/local/lib/python3.13/site-packages/sqlalchemy/util/langhelpers.py", line 146, in __exit__
    raise exc_value.with_traceback(exc_tb)
  File "/usr/local/lib/python3.13/site-packages/sqlalchemy/pool/base.py", line 897, in __connect
    self.dbapi_connection = connection = pool._invoke_creator(self)
                                         ~~~~~~~~~~~~~~~~~~~~^^^^^^
  File "/usr/local/lib/python3.13/site-packages/sqlalchemy/engine/create.py", line 646, in connect
    return dialect.connect(*cargs, **cparams)
           ~~~~~~~~~~~~~~~^^^^^^^^^^^^^^^^^^^
  File "/usr/local/lib/python3.13/site-packages/sqlalchemy/engine/default.py", line 625, in connect
    return self.loaded_dbapi.connect(*cargs, **cparams)  # type: ignore[no-any-return]  # NOQA: E501
           ~~~~~~~~~~~~~~~~~~~~~~~~~^^^^^^^^^^^^^^^^^^^
  File "/usr/local/lib/python3.13/site-packages/MySQLdb/__init__.py", line 121, in Connect
    return Connection(*args, **kwargs)
  File "/usr/local/lib/python3.13/site-packages/MySQLdb/connections.py", line 200, in __init__
    super().__init__(*args, **kwargs2)
    ~~~~~~~~~~~~~~~~^^^^^^^^^^^^^^^^^^
MySQLdb.OperationalError: (2002, "Can't connect to server on 'mariadb' (115)")

The above exception was the direct cause of the following exception:

Traceback (most recent call last):
  File "/usr/src/homeassistant/homeassistant/components/recorder/core.py", line 927, in _setup_recorder
    self._setup_connection()
    ~~~~~~~~~~~~~~~~~~~~~~^^
  File "/usr/src/homeassistant/homeassistant/components/recorder/core.py", line 1448, in _setup_connection
    migration.pre_migrate_schema(self.engine)
    ~~~~~~~~~~~~~~~~~~~~~~~~~~~~^^^^^^^^^^^^^
  File "/usr/src/homeassistant/homeassistant/components/recorder/migration.py", line 331, in pre_migrate_schema
    inspector = sqlalchemy.inspect(engine)
  File "/usr/local/lib/python3.13/site-packages/sqlalchemy/inspection.py", line 140, in inspect
    ret = reg(subject)
  File "/usr/local/lib/python3.13/site-packages/sqlalchemy/engine/reflection.py", line 313, in _engine_insp
    return Inspector._construct(Inspector._init_engine, bind)
           ~~~~~~~~~~~~~~~~~~~~^^^^^^^^^^^^^^^^^^^^^^^^^^^^^^
  File "/usr/local/lib/python3.13/site-packages/sqlalchemy/engine/reflection.py", line 246, in _construct
    init(self, bind)
    ~~~~^^^^^^^^^^^^
  File "/usr/local/lib/python3.13/site-packages/sqlalchemy/engine/reflection.py", line 257, in _init_engine
    engine.connect().close()
    ~~~~~~~~~~~~~~^^
  File "/usr/local/lib/python3.13/site-packages/sqlalchemy/engine/base.py", line 3274, in connect
    return self._connection_cls(self)
           ~~~~~~~~~~~~~~~~~~~~^^^^^^
  File "/usr/local/lib/python3.13/site-packages/sqlalchemy/engine/base.py", line 148, in __init__
    Connection._handle_dbapi_exception_noconnection(
    ~~~~~~~~~~~~~~~~~~~~~~~~~~~~~~~~~~~~~~~~~~~~~~~^
        err, dialect, engine
        ^^^^^^^^^^^^^^^^^^^^
    )
    ^
  File "/usr/local/lib/python3.13/site-packages/sqlalchemy/engine/base.py", line 2439, in _handle_dbapi_exception_noconnection
    raise sqlalchemy_exception.with_traceback(exc_info[2]) from e
  File "/usr/local/lib/python3.13/site-packages/sqlalchemy/engine/base.py", line 146, in __init__
    self._dbapi_connection = engine.raw_connection()
                             ~~~~~~~~~~~~~~~~~~~~~^^
  File "/usr/local/lib/python3.13/site-packages/sqlalchemy/engine/base.py", line 3298, in raw_connection
    return self.pool.connect()
           ~~~~~~~~~~~~~~~~~^^
  File "/usr/local/lib/python3.13/site-packages/sqlalchemy/pool/base.py", line 449, in connect
    return _ConnectionFairy._checkout(self)
           ~~~~~~~~~~~~~~~~~~~~~~~~~~^^^^^^
  File "/usr/local/lib/python3.13/site-packages/sqlalchemy/pool/base.py", line 1264, in _checkout
    fairy = _ConnectionRecord.checkout(pool)
  File "/usr/local/lib/python3.13/site-packages/sqlalchemy/pool/base.py", line 713, in checkout
    rec = pool._do_get()
  File "/usr/local/lib/python3.13/site-packages/sqlalchemy/pool/impl.py", line 179, in _do_get
    with util.safe_reraise():
         ~~~~~~~~~~~~~~~~~^^
  File "/usr/local/lib/python3.13/site-packages/sqlalchemy/util/langhelpers.py", line 146, in __exit__
    raise exc_value.with_traceback(exc_tb)
  File "/usr/local/lib/python3.13/site-packages/sqlalchemy/pool/impl.py", line 177, in _do_get
    return self._create_connection()
           ~~~~~~~~~~~~~~~~~~~~~~~^^
  File "/usr/local/lib/python3.13/site-packages/sqlalchemy/pool/base.py", line 390, in _create_connection
    return _ConnectionRecord(self)
  File "/usr/local/lib/python3.13/site-packages/sqlalchemy/pool/base.py", line 675, in __init__
    self.__connect()
    ~~~~~~~~~~~~~~^^
  File "/usr/local/lib/python3.13/site-packages/sqlalchemy/pool/base.py", line 901, in __connect
    with util.safe_reraise():
         ~~~~~~~~~~~~~~~~~^^
  File "/usr/local/lib/python3.13/site-packages/sqlalchemy/util/langhelpers.py", line 146, in __exit__
    raise exc_value.with_traceback(exc_tb)
  File "/usr/local/lib/python3.13/site-packages/sqlalchemy/pool/base.py", line 897, in __connect
    self.dbapi_connection = connection = pool._invoke_creator(self)
                                         ~~~~~~~~~~~~~~~~~~~~^^^^^^
  File "/usr/local/lib/python3.13/site-packages/sqlalchemy/engine/create.py", line 646, in connect
    return dialect.connect(*cargs, **cparams)
           ~~~~~~~~~~~~~~~^^^^^^^^^^^^^^^^^^^
  File "/usr/local/lib/python3.13/site-packages/sqlalchemy/engine/default.py", line 625, in connect
    return self.loaded_dbapi.connect(*cargs, **cparams)  # type: ignore[no-any-return]  # NOQA: E501
           ~~~~~~~~~~~~~~~~~~~~~~~~~^^^^^^^^^^^^^^^^^^^
  File "/usr/local/lib/python3.13/site-packages/MySQLdb/__init__.py", line 121, in Connect
    return Connection(*args, **kwargs)
  File "/usr/local/lib/python3.13/site-packages/MySQLdb/connections.py", line 200, in __init__
    super().__init__(*args, **kwargs2)
    ~~~~~~~~~~~~~~~~^^^^^^^^^^^^^^^^^^
sqlalchemy.exc.OperationalError: (MySQLdb.OperationalError) (2002, "Can't connect to server on 'mariadb' (115)")
(Background on this error at: https://sqlalche.me/e/20/e3q8)
2025-06-05 22:08:55.849 ERROR (Recorder) [homeassistant.components.recorder.core] Error during connection setup: (retrying in 3 seconds)
Traceback (most recent call last):
  File "/usr/local/lib/python3.13/site-packages/sqlalchemy/engine/base.py", line 146, in __init__
    self._dbapi_connection = engine.raw_connection()
                             ~~~~~~~~~~~~~~~~~~~~~^^
  File "/usr/local/lib/python3.13/site-packages/sqlalchemy/engine/base.py", line 3298, in raw_connection
    return self.pool.connect()
           ~~~~~~~~~~~~~~~~~^^
  File "/usr/local/lib/python3.13/site-packages/sqlalchemy/pool/base.py", line 449, in connect
    return _ConnectionFairy._checkout(self)
           ~~~~~~~~~~~~~~~~~~~~~~~~~~^^^^^^
  File "/usr/local/lib/python3.13/site-packages/sqlalchemy/pool/base.py", line 1264, in _checkout
    fairy = _ConnectionRecord.checkout(pool)
  File "/usr/local/lib/python3.13/site-packages/sqlalchemy/pool/base.py", line 713, in checkout
    rec = pool._do_get()
  File "/usr/local/lib/python3.13/site-packages/sqlalchemy/pool/impl.py", line 179, in _do_get
    with util.safe_reraise():
         ~~~~~~~~~~~~~~~~~^^
  File "/usr/local/lib/python3.13/site-packages/sqlalchemy/util/langhelpers.py", line 146, in __exit__
    raise exc_value.with_traceback(exc_tb)
  File "/usr/local/lib/python3.13/site-packages/sqlalchemy/pool/impl.py", line 177, in _do_get
    return self._create_connection()
           ~~~~~~~~~~~~~~~~~~~~~~~^^
  File "/usr/local/lib/python3.13/site-packages/sqlalchemy/pool/base.py", line 390, in _create_connection
    return _ConnectionRecord(self)
  File "/usr/local/lib/python3.13/site-packages/sqlalchemy/pool/base.py", line 675, in __init__
    self.__connect()
    ~~~~~~~~~~~~~~^^
  File "/usr/local/lib/python3.13/site-packages/sqlalchemy/pool/base.py", line 901, in __connect
    with util.safe_reraise():
         ~~~~~~~~~~~~~~~~~^^
  File "/usr/local/lib/python3.13/site-packages/sqlalchemy/util/langhelpers.py", line 146, in __exit__
    raise exc_value.with_traceback(exc_tb)
  File "/usr/local/lib/python3.13/site-packages/sqlalchemy/pool/base.py", line 897, in __connect
    self.dbapi_connection = connection = pool._invoke_creator(self)
                                         ~~~~~~~~~~~~~~~~~~~~^^^^^^
  File "/usr/local/lib/python3.13/site-packages/sqlalchemy/engine/create.py", line 646, in connect
    return dialect.connect(*cargs, **cparams)
           ~~~~~~~~~~~~~~~^^^^^^^^^^^^^^^^^^^
  File "/usr/local/lib/python3.13/site-packages/sqlalchemy/engine/default.py", line 625, in connect
    return self.loaded_dbapi.connect(*cargs, **cparams)  # type: ignore[no-any-return]  # NOQA: E501
           ~~~~~~~~~~~~~~~~~~~~~~~~~^^^^^^^^^^^^^^^^^^^
  File "/usr/local/lib/python3.13/site-packages/MySQLdb/__init__.py", line 121, in Connect
    return Connection(*args, **kwargs)
  File "/usr/local/lib/python3.13/site-packages/MySQLdb/connections.py", line 200, in __init__
    super().__init__(*args, **kwargs2)
    ~~~~~~~~~~~~~~~~^^^^^^^^^^^^^^^^^^
MySQLdb.OperationalError: (2002, "Can't connect to server on 'mariadb' (115)")

The above exception was the direct cause of the following exception:

Traceback (most recent call last):
  File "/usr/src/homeassistant/homeassistant/components/recorder/core.py", line 927, in _setup_recorder
    self._setup_connection()
    ~~~~~~~~~~~~~~~~~~~~~~^^
  File "/usr/src/homeassistant/homeassistant/components/recorder/core.py", line 1448, in _setup_connection
    migration.pre_migrate_schema(self.engine)
    ~~~~~~~~~~~~~~~~~~~~~~~~~~~~^^^^^^^^^^^^^
  File "/usr/src/homeassistant/homeassistant/components/recorder/migration.py", line 331, in pre_migrate_schema
    inspector = sqlalchemy.inspect(engine)
  File "/usr/local/lib/python3.13/site-packages/sqlalchemy/inspection.py", line 140, in inspect
    ret = reg(subject)
  File "/usr/local/lib/python3.13/site-packages/sqlalchemy/engine/reflection.py", line 313, in _engine_insp
    return Inspector._construct(Inspector._init_engine, bind)
           ~~~~~~~~~~~~~~~~~~~~^^^^^^^^^^^^^^^^^^^^^^^^^^^^^^
  File "/usr/local/lib/python3.13/site-packages/sqlalchemy/engine/reflection.py", line 246, in _construct
    init(self, bind)
    ~~~~^^^^^^^^^^^^
  File "/usr/local/lib/python3.13/site-packages/sqlalchemy/engine/reflection.py", line 257, in _init_engine
    engine.connect().close()
    ~~~~~~~~~~~~~~^^
  File "/usr/local/lib/python3.13/site-packages/sqlalchemy/engine/base.py", line 3274, in connect
    return self._connection_cls(self)
           ~~~~~~~~~~~~~~~~~~~~^^^^^^
  File "/usr/local/lib/python3.13/site-packages/sqlalchemy/engine/base.py", line 148, in __init__
    Connection._handle_dbapi_exception_noconnection(
    ~~~~~~~~~~~~~~~~~~~~~~~~~~~~~~~~~~~~~~~~~~~~~~~^
        err, dialect, engine
        ^^^^^^^^^^^^^^^^^^^^
    )
    ^
  File "/usr/local/lib/python3.13/site-packages/sqlalchemy/engine/base.py", line 2439, in _handle_dbapi_exception_noconnection
    raise sqlalchemy_exception.with_traceback(exc_info[2]) from e
  File "/usr/local/lib/python3.13/site-packages/sqlalchemy/engine/base.py", line 146, in __init__
    self._dbapi_connection = engine.raw_connection()
                             ~~~~~~~~~~~~~~~~~~~~~^^
  File "/usr/local/lib/python3.13/site-packages/sqlalchemy/engine/base.py", line 3298, in raw_connection
    return self.pool.connect()
           ~~~~~~~~~~~~~~~~~^^
  File "/usr/local/lib/python3.13/site-packages/sqlalchemy/pool/base.py", line 449, in connect
    return _ConnectionFairy._checkout(self)
           ~~~~~~~~~~~~~~~~~~~~~~~~~~^^^^^^
  File "/usr/local/lib/python3.13/site-packages/sqlalchemy/pool/base.py", line 1264, in _checkout
    fairy = _ConnectionRecord.checkout(pool)
  File "/usr/local/lib/python3.13/site-packages/sqlalchemy/pool/base.py", line 713, in checkout
    rec = pool._do_get()
  File "/usr/local/lib/python3.13/site-packages/sqlalchemy/pool/impl.py", line 179, in _do_get
    with util.safe_reraise():
         ~~~~~~~~~~~~~~~~~^^
  File "/usr/local/lib/python3.13/site-packages/sqlalchemy/util/langhelpers.py", line 146, in __exit__
    raise exc_value.with_traceback(exc_tb)
  File "/usr/local/lib/python3.13/site-packages/sqlalchemy/pool/impl.py", line 177, in _do_get
    return self._create_connection()
           ~~~~~~~~~~~~~~~~~~~~~~~^^
  File "/usr/local/lib/python3.13/site-packages/sqlalchemy/pool/base.py", line 390, in _create_connection
    return _ConnectionRecord(self)
  File "/usr/local/lib/python3.13/site-packages/sqlalchemy/pool/base.py", line 675, in __init__
    self.__connect()
    ~~~~~~~~~~~~~~^^
  File "/usr/local/lib/python3.13/site-packages/sqlalchemy/pool/base.py", line 901, in __connect
    with util.safe_reraise():
         ~~~~~~~~~~~~~~~~~^^
  File "/usr/local/lib/python3.13/site-packages/sqlalchemy/util/langhelpers.py", line 146, in __exit__
    raise exc_value.with_traceback(exc_tb)
  File "/usr/local/lib/python3.13/site-packages/sqlalchemy/pool/base.py", line 897, in __connect
    self.dbapi_connection = connection = pool._invoke_creator(self)
                                         ~~~~~~~~~~~~~~~~~~~~^^^^^^
  File "/usr/local/lib/python3.13/site-packages/sqlalchemy/engine/create.py", line 646, in connect
    return dialect.connect(*cargs, **cparams)
           ~~~~~~~~~~~~~~~^^^^^^^^^^^^^^^^^^^
  File "/usr/local/lib/python3.13/site-packages/sqlalchemy/engine/default.py", line 625, in connect
    return self.loaded_dbapi.connect(*cargs, **cparams)  # type: ignore[no-any-return]  # NOQA: E501
           ~~~~~~~~~~~~~~~~~~~~~~~~~^^^^^^^^^^^^^^^^^^^
  File "/usr/local/lib/python3.13/site-packages/MySQLdb/__init__.py", line 121, in Connect
    return Connection(*args, **kwargs)
  File "/usr/local/lib/python3.13/site-packages/MySQLdb/connections.py", line 200, in __init__
    super().__init__(*args, **kwargs2)
    ~~~~~~~~~~~~~~~~^^^^^^^^^^^^^^^^^^
sqlalchemy.exc.OperationalError: (MySQLdb.OperationalError) (2002, "Can't connect to server on 'mariadb' (115)")
(Background on this error at: https://sqlalche.me/e/20/e3q8)
2025-06-05 22:08:57.161 WARNING (MainThread) [homeassistant.components.http.ban] Login attempt or request with invalid authentication from i68972DBE.versanet.de (104.151.45.190). Requested URL: '/auth/token'. (Mozilla/5.0 (Macintosh; Intel Mac OS X 10_15_7) AppleWebKit/537.36 (KHTML, like Gecko) Chrome/137.0.0.0 Safari/537.36)
2025-06-05 22:08:57.923 WARNING (MainThread) [homeassistant.components.http.ban] Login attempt or request with invalid authentication from i68972DBE.versanet.de (104.151.45.190). Requested URL: '/auth/token'. (Mozilla/5.0 (Macintosh; Intel Mac OS X 10_15_7) AppleWebKit/537.36 (KHTML, like Gecko) Chrome/137.0.0.0 Safari/537.36)
2025-06-05 22:08:57.948 WARNING (MainThread) [homeassistant.components.websocket_api.http.connection] [140426135464320] from 104.151.45.190 (Mozilla/5.0 (Macintosh; Intel Mac OS X 10_15_7) AppleWebKit/537.36 (KHTML, like Gecko) Chrome/137.0.0.0 Safari/537.36): Disconnected: Received close message during auth phase
2025-06-05 22:08:58.860 ERROR (Recorder) [homeassistant.components.recorder.core] Error during connection setup: (retrying in 3 seconds)
Traceback (most recent call last):
  File "/usr/local/lib/python3.13/site-packages/sqlalchemy/engine/base.py", line 146, in __init__
    self._dbapi_connection = engine.raw_connection()
                             ~~~~~~~~~~~~~~~~~~~~~^^
  File "/usr/local/lib/python3.13/site-packages/sqlalchemy/engine/base.py", line 3298, in raw_connection
    return self.pool.connect()
           ~~~~~~~~~~~~~~~~~^^
  File "/usr/local/lib/python3.13/site-packages/sqlalchemy/pool/base.py", line 449, in connect
    return _ConnectionFairy._checkout(self)
           ~~~~~~~~~~~~~~~~~~~~~~~~~~^^^^^^
  File "/usr/local/lib/python3.13/site-packages/sqlalchemy/pool/base.py", line 1264, in _checkout
    fairy = _ConnectionRecord.checkout(pool)
  File "/usr/local/lib/python3.13/site-packages/sqlalchemy/pool/base.py", line 713, in checkout
    rec = pool._do_get()
  File "/usr/local/lib/python3.13/site-packages/sqlalchemy/pool/impl.py", line 179, in _do_get
    with util.safe_reraise():
         ~~~~~~~~~~~~~~~~~^^
  File "/usr/local/lib/python3.13/site-packages/sqlalchemy/util/langhelpers.py", line 146, in __exit__
    raise exc_value.with_traceback(exc_tb)
  File "/usr/local/lib/python3.13/site-packages/sqlalchemy/pool/impl.py", line 177, in _do_get
    return self._create_connection()
           ~~~~~~~~~~~~~~~~~~~~~~~^^
  File "/usr/local/lib/python3.13/site-packages/sqlalchemy/pool/base.py", line 390, in _create_connection
    return _ConnectionRecord(self)
  File "/usr/local/lib/python3.13/site-packages/sqlalchemy/pool/base.py", line 675, in __init__
    self.__connect()
    ~~~~~~~~~~~~~~^^
  File "/usr/local/lib/python3.13/site-packages/sqlalchemy/pool/base.py", line 901, in __connect
    with util.safe_reraise():
         ~~~~~~~~~~~~~~~~~^^
  File "/usr/local/lib/python3.13/site-packages/sqlalchemy/util/langhelpers.py", line 146, in __exit__
    raise exc_value.with_traceback(exc_tb)
  File "/usr/local/lib/python3.13/site-packages/sqlalchemy/pool/base.py", line 897, in __connect
    self.dbapi_connection = connection = pool._invoke_creator(self)
                                         ~~~~~~~~~~~~~~~~~~~~^^^^^^
  File "/usr/local/lib/python3.13/site-packages/sqlalchemy/engine/create.py", line 646, in connect
    return dialect.connect(*cargs, **cparams)
           ~~~~~~~~~~~~~~~^^^^^^^^^^^^^^^^^^^
  File "/usr/local/lib/python3.13/site-packages/sqlalchemy/engine/default.py", line 625, in connect
    return self.loaded_dbapi.connect(*cargs, **cparams)  # type: ignore[no-any-return]  # NOQA: E501
           ~~~~~~~~~~~~~~~~~~~~~~~~~^^^^^^^^^^^^^^^^^^^
  File "/usr/local/lib/python3.13/site-packages/MySQLdb/__init__.py", line 121, in Connect
    return Connection(*args, **kwargs)
  File "/usr/local/lib/python3.13/site-packages/MySQLdb/connections.py", line 200, in __init__
    super().__init__(*args, **kwargs2)
    ~~~~~~~~~~~~~~~~^^^^^^^^^^^^^^^^^^
MySQLdb.OperationalError: (2005, "Unknown server host 'mariadb' (-2)")

The above exception was the direct cause of the following exception:

Traceback (most recent call last):
  File "/usr/src/homeassistant/homeassistant/components/recorder/core.py", line 927, in _setup_recorder
    self._setup_connection()
    ~~~~~~~~~~~~~~~~~~~~~~^^
  File "/usr/src/homeassistant/homeassistant/components/recorder/core.py", line 1448, in _setup_connection
    migration.pre_migrate_schema(self.engine)
    ~~~~~~~~~~~~~~~~~~~~~~~~~~~~^^^^^^^^^^^^^
  File "/usr/src/homeassistant/homeassistant/components/recorder/migration.py", line 331, in pre_migrate_schema
    inspector = sqlalchemy.inspect(engine)
  File "/usr/local/lib/python3.13/site-packages/sqlalchemy/inspection.py", line 140, in inspect
    ret = reg(subject)
  File "/usr/local/lib/python3.13/site-packages/sqlalchemy/engine/reflection.py", line 313, in _engine_insp
    return Inspector._construct(Inspector._init_engine, bind)
           ~~~~~~~~~~~~~~~~~~~~^^^^^^^^^^^^^^^^^^^^^^^^^^^^^^
  File "/usr/local/lib/python3.13/site-packages/sqlalchemy/engine/reflection.py", line 246, in _construct
    init(self, bind)
    ~~~~^^^^^^^^^^^^
  File "/usr/local/lib/python3.13/site-packages/sqlalchemy/engine/reflection.py", line 257, in _init_engine
    engine.connect().close()
    ~~~~~~~~~~~~~~^^
  File "/usr/local/lib/python3.13/site-packages/sqlalchemy/engine/base.py", line 3274, in connect
    return self._connection_cls(self)
           ~~~~~~~~~~~~~~~~~~~~^^^^^^
  File "/usr/local/lib/python3.13/site-packages/sqlalchemy/engine/base.py", line 148, in __init__
    Connection._handle_dbapi_exception_noconnection(
    ~~~~~~~~~~~~~~~~~~~~~~~~~~~~~~~~~~~~~~~~~~~~~~~^
        err, dialect, engine
        ^^^^^^^^^^^^^^^^^^^^
    )
    ^
  File "/usr/local/lib/python3.13/site-packages/sqlalchemy/engine/base.py", line 2439, in _handle_dbapi_exception_noconnection
    raise sqlalchemy_exception.with_traceback(exc_info[2]) from e
  File "/usr/local/lib/python3.13/site-packages/sqlalchemy/engine/base.py", line 146, in __init__
    self._dbapi_connection = engine.raw_connection()
                             ~~~~~~~~~~~~~~~~~~~~~^^
  File "/usr/local/lib/python3.13/site-packages/sqlalchemy/engine/base.py", line 3298, in raw_connection
    return self.pool.connect()
           ~~~~~~~~~~~~~~~~~^^
  File "/usr/local/lib/python3.13/site-packages/sqlalchemy/pool/base.py", line 449, in connect
    return _ConnectionFairy._checkout(self)
           ~~~~~~~~~~~~~~~~~~~~~~~~~~^^^^^^
  File "/usr/local/lib/python3.13/site-packages/sqlalchemy/pool/base.py", line 1264, in _checkout
    fairy = _ConnectionRecord.checkout(pool)
  File "/usr/local/lib/python3.13/site-packages/sqlalchemy/pool/base.py", line 713, in checkout
    rec = pool._do_get()
  File "/usr/local/lib/python3.13/site-packages/sqlalchemy/pool/impl.py", line 179, in _do_get
    with util.safe_reraise():
         ~~~~~~~~~~~~~~~~~^^
  File "/usr/local/lib/python3.13/site-packages/sqlalchemy/util/langhelpers.py", line 146, in __exit__
    raise exc_value.with_traceback(exc_tb)
  File "/usr/local/lib/python3.13/site-packages/sqlalchemy/pool/impl.py", line 177, in _do_get
    return self._create_connection()
           ~~~~~~~~~~~~~~~~~~~~~~~^^
  File "/usr/local/lib/python3.13/site-packages/sqlalchemy/pool/base.py", line 390, in _create_connection
    return _ConnectionRecord(self)
  File "/usr/local/lib/python3.13/site-packages/sqlalchemy/pool/base.py", line 675, in __init__
    self.__connect()
    ~~~~~~~~~~~~~~^^
  File "/usr/local/lib/python3.13/site-packages/sqlalchemy/pool/base.py", line 901, in __connect
    with util.safe_reraise():
         ~~~~~~~~~~~~~~~~~^^
  File "/usr/local/lib/python3.13/site-packages/sqlalchemy/util/langhelpers.py", line 146, in __exit__
    raise exc_value.with_traceback(exc_tb)
  File "/usr/local/lib/python3.13/site-packages/sqlalchemy/pool/base.py", line 897, in __connect
    self.dbapi_connection = connection = pool._invoke_creator(self)
                                         ~~~~~~~~~~~~~~~~~~~~^^^^^^
  File "/usr/local/lib/python3.13/site-packages/sqlalchemy/engine/create.py", line 646, in connect
    return dialect.connect(*cargs, **cparams)
           ~~~~~~~~~~~~~~~^^^^^^^^^^^^^^^^^^^
  File "/usr/local/lib/python3.13/site-packages/sqlalchemy/engine/default.py", line 625, in connect
    return self.loaded_dbapi.connect(*cargs, **cparams)  # type: ignore[no-any-return]  # NOQA: E501
           ~~~~~~~~~~~~~~~~~~~~~~~~~^^^^^^^^^^^^^^^^^^^
  File "/usr/local/lib/python3.13/site-packages/MySQLdb/__init__.py", line 121, in Connect
    return Connection(*args, **kwargs)
  File "/usr/local/lib/python3.13/site-packages/MySQLdb/connections.py", line 200, in __init__
    super().__init__(*args, **kwargs2)
    ~~~~~~~~~~~~~~~~^^^^^^^^^^^^^^^^^^
sqlalchemy.exc.OperationalError: (MySQLdb.OperationalError) (2005, "Unknown server host 'mariadb' (-2)")
(Background on this error at: https://sqlalche.me/e/20/e3q8)
2025-06-05 22:09:01.875 ERROR (Recorder) [homeassistant.components.recorder.core] Error during connection setup: (retrying in 3 seconds)
Traceback (most recent call last):
  File "/usr/local/lib/python3.13/site-packages/sqlalchemy/engine/base.py", line 146, in __init__
    self._dbapi_connection = engine.raw_connection()
                             ~~~~~~~~~~~~~~~~~~~~~^^
  File "/usr/local/lib/python3.13/site-packages/sqlalchemy/engine/base.py", line 3298, in raw_connection
    return self.pool.connect()
           ~~~~~~~~~~~~~~~~~^^
  File "/usr/local/lib/python3.13/site-packages/sqlalchemy/pool/base.py", line 449, in connect
    return _ConnectionFairy._checkout(self)
           ~~~~~~~~~~~~~~~~~~~~~~~~~~^^^^^^
  File "/usr/local/lib/python3.13/site-packages/sqlalchemy/pool/base.py", line 1264, in _checkout
    fairy = _ConnectionRecord.checkout(pool)
  File "/usr/local/lib/python3.13/site-packages/sqlalchemy/pool/base.py", line 713, in checkout
    rec = pool._do_get()
  File "/usr/local/lib/python3.13/site-packages/sqlalchemy/pool/impl.py", line 179, in _do_get
    with util.safe_reraise():
         ~~~~~~~~~~~~~~~~~^^
  File "/usr/local/lib/python3.13/site-packages/sqlalchemy/util/langhelpers.py", line 146, in __exit__
    raise exc_value.with_traceback(exc_tb)
  File "/usr/local/lib/python3.13/site-packages/sqlalchemy/pool/impl.py", line 177, in _do_get
    return self._create_connection()
           ~~~~~~~~~~~~~~~~~~~~~~~^^
  File "/usr/local/lib/python3.13/site-packages/sqlalchemy/pool/base.py", line 390, in _create_connection
    return _ConnectionRecord(self)
  File "/usr/local/lib/python3.13/site-packages/sqlalchemy/pool/base.py", line 675, in __init__
    self.__connect()
    ~~~~~~~~~~~~~~^^
  File "/usr/local/lib/python3.13/site-packages/sqlalchemy/pool/base.py", line 901, in __connect
    with util.safe_reraise():
         ~~~~~~~~~~~~~~~~~^^
  File "/usr/local/lib/python3.13/site-packages/sqlalchemy/util/langhelpers.py", line 146, in __exit__
    raise exc_value.with_traceback(exc_tb)
  File "/usr/local/lib/python3.13/site-packages/sqlalchemy/pool/base.py", line 897, in __connect
    self.dbapi_connection = connection = pool._invoke_creator(self)
                                         ~~~~~~~~~~~~~~~~~~~~^^^^^^
  File "/usr/local/lib/python3.13/site-packages/sqlalchemy/engine/create.py", line 646, in connect
    return dialect.connect(*cargs, **cparams)
           ~~~~~~~~~~~~~~~^^^^^^^^^^^^^^^^^^^
  File "/usr/local/lib/python3.13/site-packages/sqlalchemy/engine/default.py", line 625, in connect
    return self.loaded_dbapi.connect(*cargs, **cparams)  # type: ignore[no-any-return]  # NOQA: E501
           ~~~~~~~~~~~~~~~~~~~~~~~~~^^^^^^^^^^^^^^^^^^^
  File "/usr/local/lib/python3.13/site-packages/MySQLdb/__init__.py", line 121, in Connect
    return Connection(*args, **kwargs)
  File "/usr/local/lib/python3.13/site-packages/MySQLdb/connections.py", line 200, in __init__
    super().__init__(*args, **kwargs2)
    ~~~~~~~~~~~~~~~~^^^^^^^^^^^^^^^^^^
MySQLdb.OperationalError: (2005, "Unknown server host 'mariadb' (-2)")

The above exception was the direct cause of the following exception:

Traceback (most recent call last):
  File "/usr/src/homeassistant/homeassistant/components/recorder/core.py", line 927, in _setup_recorder
    self._setup_connection()
    ~~~~~~~~~~~~~~~~~~~~~~^^
  File "/usr/src/homeassistant/homeassistant/components/recorder/core.py", line 1448, in _setup_connection
    migration.pre_migrate_schema(self.engine)
    ~~~~~~~~~~~~~~~~~~~~~~~~~~~~^^^^^^^^^^^^^
  File "/usr/src/homeassistant/homeassistant/components/recorder/migration.py", line 331, in pre_migrate_schema
    inspector = sqlalchemy.inspect(engine)
  File "/usr/local/lib/python3.13/site-packages/sqlalchemy/inspection.py", line 140, in inspect
    ret = reg(subject)
  File "/usr/local/lib/python3.13/site-packages/sqlalchemy/engine/reflection.py", line 313, in _engine_insp
    return Inspector._construct(Inspector._init_engine, bind)
           ~~~~~~~~~~~~~~~~~~~~^^^^^^^^^^^^^^^^^^^^^^^^^^^^^^
  File "/usr/local/lib/python3.13/site-packages/sqlalchemy/engine/reflection.py", line 246, in _construct
    init(self, bind)
    ~~~~^^^^^^^^^^^^
  File "/usr/local/lib/python3.13/site-packages/sqlalchemy/engine/reflection.py", line 257, in _init_engine
    engine.connect().close()
    ~~~~~~~~~~~~~~^^
  File "/usr/local/lib/python3.13/site-packages/sqlalchemy/engine/base.py", line 3274, in connect
    return self._connection_cls(self)
           ~~~~~~~~~~~~~~~~~~~~^^^^^^
  File "/usr/local/lib/python3.13/site-packages/sqlalchemy/engine/base.py", line 148, in __init__
    Connection._handle_dbapi_exception_noconnection(
    ~~~~~~~~~~~~~~~~~~~~~~~~~~~~~~~~~~~~~~~~~~~~~~~^
        err, dialect, engine
        ^^^^^^^^^^^^^^^^^^^^
    )
    ^
  File "/usr/local/lib/python3.13/site-packages/sqlalchemy/engine/base.py", line 2439, in _handle_dbapi_exception_noconnection
    raise sqlalchemy_exception.with_traceback(exc_info[2]) from e
  File "/usr/local/lib/python3.13/site-packages/sqlalchemy/engine/base.py", line 146, in __init__
    self._dbapi_connection = engine.raw_connection()
                             ~~~~~~~~~~~~~~~~~~~~~^^
  File "/usr/local/lib/python3.13/site-packages/sqlalchemy/engine/base.py", line 3298, in raw_connection
    return self.pool.connect()
           ~~~~~~~~~~~~~~~~~^^
  File "/usr/local/lib/python3.13/site-packages/sqlalchemy/pool/base.py", line 449, in connect
    return _ConnectionFairy._checkout(self)
           ~~~~~~~~~~~~~~~~~~~~~~~~~~^^^^^^
  File "/usr/local/lib/python3.13/site-packages/sqlalchemy/pool/base.py", line 1264, in _checkout
    fairy = _ConnectionRecord.checkout(pool)
  File "/usr/local/lib/python3.13/site-packages/sqlalchemy/pool/base.py", line 713, in checkout
    rec = pool._do_get()
  File "/usr/local/lib/python3.13/site-packages/sqlalchemy/pool/impl.py", line 179, in _do_get
    with util.safe_reraise():
         ~~~~~~~~~~~~~~~~~^^
  File "/usr/local/lib/python3.13/site-packages/sqlalchemy/util/langhelpers.py", line 146, in __exit__
    raise exc_value.with_traceback(exc_tb)
  File "/usr/local/lib/python3.13/site-packages/sqlalchemy/pool/impl.py", line 177, in _do_get
    return self._create_connection()
           ~~~~~~~~~~~~~~~~~~~~~~~^^
  File "/usr/local/lib/python3.13/site-packages/sqlalchemy/pool/base.py", line 390, in _create_connection
    return _ConnectionRecord(self)
  File "/usr/local/lib/python3.13/site-packages/sqlalchemy/pool/base.py", line 675, in __init__
    self.__connect()
    ~~~~~~~~~~~~~~^^
  File "/usr/local/lib/python3.13/site-packages/sqlalchemy/pool/base.py", line 901, in __connect
    with util.safe_reraise():
         ~~~~~~~~~~~~~~~~~^^
  File "/usr/local/lib/python3.13/site-packages/sqlalchemy/util/langhelpers.py", line 146, in __exit__
    raise exc_value.with_traceback(exc_tb)
  File "/usr/local/lib/python3.13/site-packages/sqlalchemy/pool/base.py", line 897, in __connect
    self.dbapi_connection = connection = pool._invoke_creator(self)
                                         ~~~~~~~~~~~~~~~~~~~~^^^^^^
  File "/usr/local/lib/python3.13/site-packages/sqlalchemy/engine/create.py", line 646, in connect
    return dialect.connect(*cargs, **cparams)
           ~~~~~~~~~~~~~~~^^^^^^^^^^^^^^^^^^^
  File "/usr/local/lib/python3.13/site-packages/sqlalchemy/engine/default.py", line 625, in connect
    return self.loaded_dbapi.connect(*cargs, **cparams)  # type: ignore[no-any-return]  # NOQA: E501
           ~~~~~~~~~~~~~~~~~~~~~~~~~^^^^^^^^^^^^^^^^^^^
  File "/usr/local/lib/python3.13/site-packages/MySQLdb/__init__.py", line 121, in Connect
    return Connection(*args, **kwargs)
  File "/usr/local/lib/python3.13/site-packages/MySQLdb/connections.py", line 200, in __init__
    super().__init__(*args, **kwargs2)
    ~~~~~~~~~~~~~~~~^^^^^^^^^^^^^^^^^^
sqlalchemy.exc.OperationalError: (MySQLdb.OperationalError) (2005, "Unknown server host 'mariadb' (-2)")
(Background on this error at: https://sqlalche.me/e/20/e3q8)
2025-06-05 22:09:02.770 WARNING (MainThread) [homeassistant.setup] Setup of recorder is taking over 10 seconds.
2025-06-05 22:09:04.886 ERROR (Recorder) [homeassistant.components.recorder.core] Error during connection setup: (retrying in 3 seconds)
Traceback (most recent call last):
  File "/usr/local/lib/python3.13/site-packages/sqlalchemy/engine/base.py", line 146, in __init__
    self._dbapi_connection = engine.raw_connection()
                             ~~~~~~~~~~~~~~~~~~~~~^^
  File "/usr/local/lib/python3.13/site-packages/sqlalchemy/engine/base.py", line 3298, in raw_connection
    return self.pool.connect()
           ~~~~~~~~~~~~~~~~~^^
  File "/usr/local/lib/python3.13/site-packages/sqlalchemy/pool/base.py", line 449, in connect
    return _ConnectionFairy._checkout(self)
           ~~~~~~~~~~~~~~~~~~~~~~~~~~^^^^^^
  File "/usr/local/lib/python3.13/site-packages/sqlalchemy/pool/base.py", line 1264, in _checkout
    fairy = _ConnectionRecord.checkout(pool)
  File "/usr/local/lib/python3.13/site-packages/sqlalchemy/pool/base.py", line 713, in checkout
    rec = pool._do_get()
  File "/usr/local/lib/python3.13/site-packages/sqlalchemy/pool/impl.py", line 179, in _do_get
    with util.safe_reraise():
         ~~~~~~~~~~~~~~~~~^^
  File "/usr/local/lib/python3.13/site-packages/sqlalchemy/util/langhelpers.py", line 146, in __exit__
    raise exc_value.with_traceback(exc_tb)
  File "/usr/local/lib/python3.13/site-packages/sqlalchemy/pool/impl.py", line 177, in _do_get
    return self._create_connection()
           ~~~~~~~~~~~~~~~~~~~~~~~^^
  File "/usr/local/lib/python3.13/site-packages/sqlalchemy/pool/base.py", line 390, in _create_connection
    return _ConnectionRecord(self)
  File "/usr/local/lib/python3.13/site-packages/sqlalchemy/pool/base.py", line 675, in __init__
    self.__connect()
    ~~~~~~~~~~~~~~^^
  File "/usr/local/lib/python3.13/site-packages/sqlalchemy/pool/base.py", line 901, in __connect
    with util.safe_reraise():
         ~~~~~~~~~~~~~~~~~^^
  File "/usr/local/lib/python3.13/site-packages/sqlalchemy/util/langhelpers.py", line 146, in __exit__
    raise exc_value.with_traceback(exc_tb)
  File "/usr/local/lib/python3.13/site-packages/sqlalchemy/pool/base.py", line 897, in __connect
    self.dbapi_connection = connection = pool._invoke_creator(self)
                                         ~~~~~~~~~~~~~~~~~~~~^^^^^^
  File "/usr/local/lib/python3.13/site-packages/sqlalchemy/engine/create.py", line 646, in connect
    return dialect.connect(*cargs, **cparams)
           ~~~~~~~~~~~~~~~^^^^^^^^^^^^^^^^^^^
  File "/usr/local/lib/python3.13/site-packages/sqlalchemy/engine/default.py", line 625, in connect
    return self.loaded_dbapi.connect(*cargs, **cparams)  # type: ignore[no-any-return]  # NOQA: E501
           ~~~~~~~~~~~~~~~~~~~~~~~~~^^^^^^^^^^^^^^^^^^^
  File "/usr/local/lib/python3.13/site-packages/MySQLdb/__init__.py", line 121, in Connect
    return Connection(*args, **kwargs)
  File "/usr/local/lib/python3.13/site-packages/MySQLdb/connections.py", line 200, in __init__
    super().__init__(*args, **kwargs2)
    ~~~~~~~~~~~~~~~~^^^^^^^^^^^^^^^^^^
MySQLdb.OperationalError: (2005, "Unknown server host 'mariadb' (-2)")

The above exception was the direct cause of the following exception:

Traceback (most recent call last):
  File "/usr/src/homeassistant/homeassistant/components/recorder/core.py", line 927, in _setup_recorder
    self._setup_connection()
    ~~~~~~~~~~~~~~~~~~~~~~^^
  File "/usr/src/homeassistant/homeassistant/components/recorder/core.py", line 1448, in _setup_connection
    migration.pre_migrate_schema(self.engine)
    ~~~~~~~~~~~~~~~~~~~~~~~~~~~~^^^^^^^^^^^^^
  File "/usr/src/homeassistant/homeassistant/components/recorder/migration.py", line 331, in pre_migrate_schema
    inspector = sqlalchemy.inspect(engine)
  File "/usr/local/lib/python3.13/site-packages/sqlalchemy/inspection.py", line 140, in inspect
    ret = reg(subject)
  File "/usr/local/lib/python3.13/site-packages/sqlalchemy/engine/reflection.py", line 313, in _engine_insp
    return Inspector._construct(Inspector._init_engine, bind)
           ~~~~~~~~~~~~~~~~~~~~^^^^^^^^^^^^^^^^^^^^^^^^^^^^^^
  File "/usr/local/lib/python3.13/site-packages/sqlalchemy/engine/reflection.py", line 246, in _construct
    init(self, bind)
    ~~~~^^^^^^^^^^^^
  File "/usr/local/lib/python3.13/site-packages/sqlalchemy/engine/reflection.py", line 257, in _init_engine
    engine.connect().close()
    ~~~~~~~~~~~~~~^^
  File "/usr/local/lib/python3.13/site-packages/sqlalchemy/engine/base.py", line 3274, in connect
    return self._connection_cls(self)
           ~~~~~~~~~~~~~~~~~~~~^^^^^^
  File "/usr/local/lib/python3.13/site-packages/sqlalchemy/engine/base.py", line 148, in __init__
    Connection._handle_dbapi_exception_noconnection(
    ~~~~~~~~~~~~~~~~~~~~~~~~~~~~~~~~~~~~~~~~~~~~~~~^
        err, dialect, engine
        ^^^^^^^^^^^^^^^^^^^^
    )
    ^
  File "/usr/local/lib/python3.13/site-packages/sqlalchemy/engine/base.py", line 2439, in _handle_dbapi_exception_noconnection
    raise sqlalchemy_exception.with_traceback(exc_info[2]) from e
  File "/usr/local/lib/python3.13/site-packages/sqlalchemy/engine/base.py", line 146, in __init__
    self._dbapi_connection = engine.raw_connection()
                             ~~~~~~~~~~~~~~~~~~~~~^^
  File "/usr/local/lib/python3.13/site-packages/sqlalchemy/engine/base.py", line 3298, in raw_connection
    return self.pool.connect()
           ~~~~~~~~~~~~~~~~~^^
  File "/usr/local/lib/python3.13/site-packages/sqlalchemy/pool/base.py", line 449, in connect
    return _ConnectionFairy._checkout(self)
           ~~~~~~~~~~~~~~~~~~~~~~~~~~^^^^^^
  File "/usr/local/lib/python3.13/site-packages/sqlalchemy/pool/base.py", line 1264, in _checkout
    fairy = _ConnectionRecord.checkout(pool)
  File "/usr/local/lib/python3.13/site-packages/sqlalchemy/pool/base.py", line 713, in checkout
    rec = pool._do_get()
  File "/usr/local/lib/python3.13/site-packages/sqlalchemy/pool/impl.py", line 179, in _do_get
    with util.safe_reraise():
         ~~~~~~~~~~~~~~~~~^^
  File "/usr/local/lib/python3.13/site-packages/sqlalchemy/util/langhelpers.py", line 146, in __exit__
    raise exc_value.with_traceback(exc_tb)
  File "/usr/local/lib/python3.13/site-packages/sqlalchemy/pool/impl.py", line 177, in _do_get
    return self._create_connection()
           ~~~~~~~~~~~~~~~~~~~~~~~^^
  File "/usr/local/lib/python3.13/site-packages/sqlalchemy/pool/base.py", line 390, in _create_connection
    return _ConnectionRecord(self)
  File "/usr/local/lib/python3.13/site-packages/sqlalchemy/pool/base.py", line 675, in __init__
    self.__connect()
    ~~~~~~~~~~~~~~^^
  File "/usr/local/lib/python3.13/site-packages/sqlalchemy/pool/base.py", line 901, in __connect
    with util.safe_reraise():
         ~~~~~~~~~~~~~~~~~^^
  File "/usr/local/lib/python3.13/site-packages/sqlalchemy/util/langhelpers.py", line 146, in __exit__
    raise exc_value.with_traceback(exc_tb)
  File "/usr/local/lib/python3.13/site-packages/sqlalchemy/pool/base.py", line 897, in __connect
    self.dbapi_connection = connection = pool._invoke_creator(self)
                                         ~~~~~~~~~~~~~~~~~~~~^^^^^^
  File "/usr/local/lib/python3.13/site-packages/sqlalchemy/engine/create.py", line 646, in connect
    return dialect.connect(*cargs, **cparams)
           ~~~~~~~~~~~~~~~^^^^^^^^^^^^^^^^^^^
  File "/usr/local/lib/python3.13/site-packages/sqlalchemy/engine/default.py", line 625, in connect
    return self.loaded_dbapi.connect(*cargs, **cparams)  # type: ignore[no-any-return]  # NOQA: E501
           ~~~~~~~~~~~~~~~~~~~~~~~~~^^^^^^^^^^^^^^^^^^^
  File "/usr/local/lib/python3.13/site-packages/MySQLdb/__init__.py", line 121, in Connect
    return Connection(*args, **kwargs)
  File "/usr/local/lib/python3.13/site-packages/MySQLdb/connections.py", line 200, in __init__
    super().__init__(*args, **kwargs2)
    ~~~~~~~~~~~~~~~~^^^^^^^^^^^^^^^^^^
sqlalchemy.exc.OperationalError: (MySQLdb.OperationalError) (2005, "Unknown server host 'mariadb' (-2)")
(Background on this error at: https://sqlalche.me/e/20/e3q8)
2025-06-05 22:09:07.892 ERROR (Recorder) [homeassistant.components.recorder.core] Error during connection setup: (retrying in 3 seconds)
Traceback (most recent call last):
  File "/usr/local/lib/python3.13/site-packages/sqlalchemy/engine/base.py", line 146, in __init__
    self._dbapi_connection = engine.raw_connection()
                             ~~~~~~~~~~~~~~~~~~~~~^^
  File "/usr/local/lib/python3.13/site-packages/sqlalchemy/engine/base.py", line 3298, in raw_connection
    return self.pool.connect()
           ~~~~~~~~~~~~~~~~~^^
  File "/usr/local/lib/python3.13/site-packages/sqlalchemy/pool/base.py", line 449, in connect
    return _ConnectionFairy._checkout(self)
           ~~~~~~~~~~~~~~~~~~~~~~~~~~^^^^^^
  File "/usr/local/lib/python3.13/site-packages/sqlalchemy/pool/base.py", line 1264, in _checkout
    fairy = _ConnectionRecord.checkout(pool)
  File "/usr/local/lib/python3.13/site-packages/sqlalchemy/pool/base.py", line 713, in checkout
    rec = pool._do_get()
  File "/usr/local/lib/python3.13/site-packages/sqlalchemy/pool/impl.py", line 179, in _do_get
    with util.safe_reraise():
         ~~~~~~~~~~~~~~~~~^^
  File "/usr/local/lib/python3.13/site-packages/sqlalchemy/util/langhelpers.py", line 146, in __exit__
    raise exc_value.with_traceback(exc_tb)
  File "/usr/local/lib/python3.13/site-packages/sqlalchemy/pool/impl.py", line 177, in _do_get
    return self._create_connection()
           ~~~~~~~~~~~~~~~~~~~~~~~^^
  File "/usr/local/lib/python3.13/site-packages/sqlalchemy/pool/base.py", line 390, in _create_connection
    return _ConnectionRecord(self)
  File "/usr/local/lib/python3.13/site-packages/sqlalchemy/pool/base.py", line 675, in __init__
    self.__connect()
    ~~~~~~~~~~~~~~^^
  File "/usr/local/lib/python3.13/site-packages/sqlalchemy/pool/base.py", line 901, in __connect
    with util.safe_reraise():
         ~~~~~~~~~~~~~~~~~^^
  File "/usr/local/lib/python3.13/site-packages/sqlalchemy/util/langhelpers.py", line 146, in __exit__
    raise exc_value.with_traceback(exc_tb)
  File "/usr/local/lib/python3.13/site-packages/sqlalchemy/pool/base.py", line 897, in __connect
    self.dbapi_connection = connection = pool._invoke_creator(self)
                                         ~~~~~~~~~~~~~~~~~~~~^^^^^^
  File "/usr/local/lib/python3.13/site-packages/sqlalchemy/engine/create.py", line 646, in connect
    return dialect.connect(*cargs, **cparams)
           ~~~~~~~~~~~~~~~^^^^^^^^^^^^^^^^^^^
  File "/usr/local/lib/python3.13/site-packages/sqlalchemy/engine/default.py", line 625, in connect
    return self.loaded_dbapi.connect(*cargs, **cparams)  # type: ignore[no-any-return]  # NOQA: E501
           ~~~~~~~~~~~~~~~~~~~~~~~~~^^^^^^^^^^^^^^^^^^^
  File "/usr/local/lib/python3.13/site-packages/MySQLdb/__init__.py", line 121, in Connect
    return Connection(*args, **kwargs)
  File "/usr/local/lib/python3.13/site-packages/MySQLdb/connections.py", line 200, in __init__
    super().__init__(*args, **kwargs2)
    ~~~~~~~~~~~~~~~~^^^^^^^^^^^^^^^^^^
MySQLdb.OperationalError: (2002, "Can't connect to server on 'mariadb' (115)")

The above exception was the direct cause of the following exception:

Traceback (most recent call last):
  File "/usr/src/homeassistant/homeassistant/components/recorder/core.py", line 927, in _setup_recorder
    self._setup_connection()
    ~~~~~~~~~~~~~~~~~~~~~~^^
  File "/usr/src/homeassistant/homeassistant/components/recorder/core.py", line 1448, in _setup_connection
    migration.pre_migrate_schema(self.engine)
    ~~~~~~~~~~~~~~~~~~~~~~~~~~~~^^^^^^^^^^^^^
  File "/usr/src/homeassistant/homeassistant/components/recorder/migration.py", line 331, in pre_migrate_schema
    inspector = sqlalchemy.inspect(engine)
  File "/usr/local/lib/python3.13/site-packages/sqlalchemy/inspection.py", line 140, in inspect
    ret = reg(subject)
  File "/usr/local/lib/python3.13/site-packages/sqlalchemy/engine/reflection.py", line 313, in _engine_insp
    return Inspector._construct(Inspector._init_engine, bind)
           ~~~~~~~~~~~~~~~~~~~~^^^^^^^^^^^^^^^^^^^^^^^^^^^^^^
  File "/usr/local/lib/python3.13/site-packages/sqlalchemy/engine/reflection.py", line 246, in _construct
    init(self, bind)
    ~~~~^^^^^^^^^^^^
  File "/usr/local/lib/python3.13/site-packages/sqlalchemy/engine/reflection.py", line 257, in _init_engine
    engine.connect().close()
    ~~~~~~~~~~~~~~^^
  File "/usr/local/lib/python3.13/site-packages/sqlalchemy/engine/base.py", line 3274, in connect
    return self._connection_cls(self)
           ~~~~~~~~~~~~~~~~~~~~^^^^^^
  File "/usr/local/lib/python3.13/site-packages/sqlalchemy/engine/base.py", line 148, in __init__
    Connection._handle_dbapi_exception_noconnection(
    ~~~~~~~~~~~~~~~~~~~~~~~~~~~~~~~~~~~~~~~~~~~~~~~^
        err, dialect, engine
        ^^^^^^^^^^^^^^^^^^^^
    )
    ^
  File "/usr/local/lib/python3.13/site-packages/sqlalchemy/engine/base.py", line 2439, in _handle_dbapi_exception_noconnection
    raise sqlalchemy_exception.with_traceback(exc_info[2]) from e
  File "/usr/local/lib/python3.13/site-packages/sqlalchemy/engine/base.py", line 146, in __init__
    self._dbapi_connection = engine.raw_connection()
                             ~~~~~~~~~~~~~~~~~~~~~^^
  File "/usr/local/lib/python3.13/site-packages/sqlalchemy/engine/base.py", line 3298, in raw_connection
    return self.pool.connect()
           ~~~~~~~~~~~~~~~~~^^
  File "/usr/local/lib/python3.13/site-packages/sqlalchemy/pool/base.py", line 449, in connect
    return _ConnectionFairy._checkout(self)
           ~~~~~~~~~~~~~~~~~~~~~~~~~~^^^^^^
  File "/usr/local/lib/python3.13/site-packages/sqlalchemy/pool/base.py", line 1264, in _checkout
    fairy = _ConnectionRecord.checkout(pool)
  File "/usr/local/lib/python3.13/site-packages/sqlalchemy/pool/base.py", line 713, in checkout
    rec = pool._do_get()
  File "/usr/local/lib/python3.13/site-packages/sqlalchemy/pool/impl.py", line 179, in _do_get
    with util.safe_reraise():
         ~~~~~~~~~~~~~~~~~^^
  File "/usr/local/lib/python3.13/site-packages/sqlalchemy/util/langhelpers.py", line 146, in __exit__
    raise exc_value.with_traceback(exc_tb)
  File "/usr/local/lib/python3.13/site-packages/sqlalchemy/pool/impl.py", line 177, in _do_get
    return self._create_connection()
           ~~~~~~~~~~~~~~~~~~~~~~~^^
  File "/usr/local/lib/python3.13/site-packages/sqlalchemy/pool/base.py", line 390, in _create_connection
    return _ConnectionRecord(self)
  File "/usr/local/lib/python3.13/site-packages/sqlalchemy/pool/base.py", line 675, in __init__
    self.__connect()
    ~~~~~~~~~~~~~~^^
  File "/usr/local/lib/python3.13/site-packages/sqlalchemy/pool/base.py", line 901, in __connect
    with util.safe_reraise():
         ~~~~~~~~~~~~~~~~~^^
  File "/usr/local/lib/python3.13/site-packages/sqlalchemy/util/langhelpers.py", line 146, in __exit__
    raise exc_value.with_traceback(exc_tb)
  File "/usr/local/lib/python3.13/site-packages/sqlalchemy/pool/base.py", line 897, in __connect
    self.dbapi_connection = connection = pool._invoke_creator(self)
                                         ~~~~~~~~~~~~~~~~~~~~^^^^^^
  File "/usr/local/lib/python3.13/site-packages/sqlalchemy/engine/create.py", line 646, in connect
    return dialect.connect(*cargs, **cparams)
           ~~~~~~~~~~~~~~~^^^^^^^^^^^^^^^^^^^
  File "/usr/local/lib/python3.13/site-packages/sqlalchemy/engine/default.py", line 625, in connect
    return self.loaded_dbapi.connect(*cargs, **cparams)  # type: ignore[no-any-return]  # NOQA: E501
           ~~~~~~~~~~~~~~~~~~~~~~~~~^^^^^^^^^^^^^^^^^^^
  File "/usr/local/lib/python3.13/site-packages/MySQLdb/__init__.py", line 121, in Connect
    return Connection(*args, **kwargs)
  File "/usr/local/lib/python3.13/site-packages/MySQLdb/connections.py", line 200, in __init__
    super().__init__(*args, **kwargs2)
    ~~~~~~~~~~~~~~~~^^^^^^^^^^^^^^^^^^
sqlalchemy.exc.OperationalError: (MySQLdb.OperationalError) (2002, "Can't connect to server on 'mariadb' (115)")
(Background on this error at: https://sqlalche.me/e/20/e3q8)
2025-06-05 22:09:10.906 ERROR (Recorder) [homeassistant.components.recorder.core] Error during connection setup: (retrying in 3 seconds)
Traceback (most recent call last):
  File "/usr/local/lib/python3.13/site-packages/sqlalchemy/engine/base.py", line 146, in __init__
    self._dbapi_connection = engine.raw_connection()
                             ~~~~~~~~~~~~~~~~~~~~~^^
  File "/usr/local/lib/python3.13/site-packages/sqlalchemy/engine/base.py", line 3298, in raw_connection
    return self.pool.connect()
           ~~~~~~~~~~~~~~~~~^^
  File "/usr/local/lib/python3.13/site-packages/sqlalchemy/pool/base.py", line 449, in connect
    return _ConnectionFairy._checkout(self)
           ~~~~~~~~~~~~~~~~~~~~~~~~~~^^^^^^
  File "/usr/local/lib/python3.13/site-packages/sqlalchemy/pool/base.py", line 1264, in _checkout
    fairy = _ConnectionRecord.checkout(pool)
  File "/usr/local/lib/python3.13/site-packages/sqlalchemy/pool/base.py", line 713, in checkout
    rec = pool._do_get()
  File "/usr/local/lib/python3.13/site-packages/sqlalchemy/pool/impl.py", line 179, in _do_get
    with util.safe_reraise():
         ~~~~~~~~~~~~~~~~~^^
  File "/usr/local/lib/python3.13/site-packages/sqlalchemy/util/langhelpers.py", line 146, in __exit__
    raise exc_value.with_traceback(exc_tb)
  File "/usr/local/lib/python3.13/site-packages/sqlalchemy/pool/impl.py", line 177, in _do_get
    return self._create_connection()
           ~~~~~~~~~~~~~~~~~~~~~~~^^
  File "/usr/local/lib/python3.13/site-packages/sqlalchemy/pool/base.py", line 390, in _create_connection
    return _ConnectionRecord(self)
  File "/usr/local/lib/python3.13/site-packages/sqlalchemy/pool/base.py", line 675, in __init__
    self.__connect()
    ~~~~~~~~~~~~~~^^
  File "/usr/local/lib/python3.13/site-packages/sqlalchemy/pool/base.py", line 901, in __connect
    with util.safe_reraise():
         ~~~~~~~~~~~~~~~~~^^
  File "/usr/local/lib/python3.13/site-packages/sqlalchemy/util/langhelpers.py", line 146, in __exit__
    raise exc_value.with_traceback(exc_tb)
  File "/usr/local/lib/python3.13/site-packages/sqlalchemy/pool/base.py", line 897, in __connect
    self.dbapi_connection = connection = pool._invoke_creator(self)
                                         ~~~~~~~~~~~~~~~~~~~~^^^^^^
  File "/usr/local/lib/python3.13/site-packages/sqlalchemy/engine/create.py", line 646, in connect
    return dialect.connect(*cargs, **cparams)
           ~~~~~~~~~~~~~~~^^^^^^^^^^^^^^^^^^^
  File "/usr/local/lib/python3.13/site-packages/sqlalchemy/engine/default.py", line 625, in connect
    return self.loaded_dbapi.connect(*cargs, **cparams)  # type: ignore[no-any-return]  # NOQA: E501
           ~~~~~~~~~~~~~~~~~~~~~~~~~^^^^^^^^^^^^^^^^^^^
  File "/usr/local/lib/python3.13/site-packages/MySQLdb/__init__.py", line 121, in Connect
    return Connection(*args, **kwargs)
  File "/usr/local/lib/python3.13/site-packages/MySQLdb/connections.py", line 200, in __init__
    super().__init__(*args, **kwargs2)
    ~~~~~~~~~~~~~~~~^^^^^^^^^^^^^^^^^^
MySQLdb.OperationalError: (2005, "Unknown server host 'mariadb' (-2)")

The above exception was the direct cause of the following exception:

Traceback (most recent call last):
  File "/usr/src/homeassistant/homeassistant/components/recorder/core.py", line 927, in _setup_recorder
    self._setup_connection()
    ~~~~~~~~~~~~~~~~~~~~~~^^
  File "/usr/src/homeassistant/homeassistant/components/recorder/core.py", line 1448, in _setup_connection
    migration.pre_migrate_schema(self.engine)
    ~~~~~~~~~~~~~~~~~~~~~~~~~~~~^^^^^^^^^^^^^
  File "/usr/src/homeassistant/homeassistant/components/recorder/migration.py", line 331, in pre_migrate_schema
    inspector = sqlalchemy.inspect(engine)
  File "/usr/local/lib/python3.13/site-packages/sqlalchemy/inspection.py", line 140, in inspect
    ret = reg(subject)
  File "/usr/local/lib/python3.13/site-packages/sqlalchemy/engine/reflection.py", line 313, in _engine_insp
    return Inspector._construct(Inspector._init_engine, bind)
           ~~~~~~~~~~~~~~~~~~~~^^^^^^^^^^^^^^^^^^^^^^^^^^^^^^
  File "/usr/local/lib/python3.13/site-packages/sqlalchemy/engine/reflection.py", line 246, in _construct
    init(self, bind)
    ~~~~^^^^^^^^^^^^
  File "/usr/local/lib/python3.13/site-packages/sqlalchemy/engine/reflection.py", line 257, in _init_engine
    engine.connect().close()
    ~~~~~~~~~~~~~~^^
  File "/usr/local/lib/python3.13/site-packages/sqlalchemy/engine/base.py", line 3274, in connect
    return self._connection_cls(self)
           ~~~~~~~~~~~~~~~~~~~~^^^^^^
  File "/usr/local/lib/python3.13/site-packages/sqlalchemy/engine/base.py", line 148, in __init__
    Connection._handle_dbapi_exception_noconnection(
    ~~~~~~~~~~~~~~~~~~~~~~~~~~~~~~~~~~~~~~~~~~~~~~~^
        err, dialect, engine
        ^^^^^^^^^^^^^^^^^^^^
    )
    ^
  File "/usr/local/lib/python3.13/site-packages/sqlalchemy/engine/base.py", line 2439, in _handle_dbapi_exception_noconnection
    raise sqlalchemy_exception.with_traceback(exc_info[2]) from e
  File "/usr/local/lib/python3.13/site-packages/sqlalchemy/engine/base.py", line 146, in __init__
    self._dbapi_connection = engine.raw_connection()
                             ~~~~~~~~~~~~~~~~~~~~~^^
  File "/usr/local/lib/python3.13/site-packages/sqlalchemy/engine/base.py", line 3298, in raw_connection
    return self.pool.connect()
           ~~~~~~~~~~~~~~~~~^^
  File "/usr/local/lib/python3.13/site-packages/sqlalchemy/pool/base.py", line 449, in connect
    return _ConnectionFairy._checkout(self)
           ~~~~~~~~~~~~~~~~~~~~~~~~~~^^^^^^
  File "/usr/local/lib/python3.13/site-packages/sqlalchemy/pool/base.py", line 1264, in _checkout
    fairy = _ConnectionRecord.checkout(pool)
  File "/usr/local/lib/python3.13/site-packages/sqlalchemy/pool/base.py", line 713, in checkout
    rec = pool._do_get()
  File "/usr/local/lib/python3.13/site-packages/sqlalchemy/pool/impl.py", line 179, in _do_get
    with util.safe_reraise():
         ~~~~~~~~~~~~~~~~~^^
  File "/usr/local/lib/python3.13/site-packages/sqlalchemy/util/langhelpers.py", line 146, in __exit__
    raise exc_value.with_traceback(exc_tb)
  File "/usr/local/lib/python3.13/site-packages/sqlalchemy/pool/impl.py", line 177, in _do_get
    return self._create_connection()
           ~~~~~~~~~~~~~~~~~~~~~~~^^
  File "/usr/local/lib/python3.13/site-packages/sqlalchemy/pool/base.py", line 390, in _create_connection
    return _ConnectionRecord(self)
  File "/usr/local/lib/python3.13/site-packages/sqlalchemy/pool/base.py", line 675, in __init__
    self.__connect()
    ~~~~~~~~~~~~~~^^
  File "/usr/local/lib/python3.13/site-packages/sqlalchemy/pool/base.py", line 901, in __connect
    with util.safe_reraise():
         ~~~~~~~~~~~~~~~~~^^
  File "/usr/local/lib/python3.13/site-packages/sqlalchemy/util/langhelpers.py", line 146, in __exit__
    raise exc_value.with_traceback(exc_tb)
  File "/usr/local/lib/python3.13/site-packages/sqlalchemy/pool/base.py", line 897, in __connect
    self.dbapi_connection = connection = pool._invoke_creator(self)
                                         ~~~~~~~~~~~~~~~~~~~~^^^^^^
  File "/usr/local/lib/python3.13/site-packages/sqlalchemy/engine/create.py", line 646, in connect
    return dialect.connect(*cargs, **cparams)
           ~~~~~~~~~~~~~~~^^^^^^^^^^^^^^^^^^^
  File "/usr/local/lib/python3.13/site-packages/sqlalchemy/engine/default.py", line 625, in connect
    return self.loaded_dbapi.connect(*cargs, **cparams)  # type: ignore[no-any-return]  # NOQA: E501
           ~~~~~~~~~~~~~~~~~~~~~~~~~^^^^^^^^^^^^^^^^^^^
  File "/usr/local/lib/python3.13/site-packages/MySQLdb/__init__.py", line 121, in Connect
    return Connection(*args, **kwargs)
  File "/usr/local/lib/python3.13/site-packages/MySQLdb/connections.py", line 200, in __init__
    super().__init__(*args, **kwargs2)
    ~~~~~~~~~~~~~~~~^^^^^^^^^^^^^^^^^^
sqlalchemy.exc.OperationalError: (MySQLdb.OperationalError) (2005, "Unknown server host 'mariadb' (-2)")
(Background on this error at: https://sqlalche.me/e/20/e3q8)
2025-06-05 22:09:13.916 ERROR (Recorder) [homeassistant.components.recorder.core] Error during connection setup: (retrying in 3 seconds)
Traceback (most recent call last):
  File "/usr/local/lib/python3.13/site-packages/sqlalchemy/engine/base.py", line 146, in __init__
    self._dbapi_connection = engine.raw_connection()
                             ~~~~~~~~~~~~~~~~~~~~~^^
  File "/usr/local/lib/python3.13/site-packages/sqlalchemy/engine/base.py", line 3298, in raw_connection
    return self.pool.connect()
           ~~~~~~~~~~~~~~~~~^^
  File "/usr/local/lib/python3.13/site-packages/sqlalchemy/pool/base.py", line 449, in connect
    return _ConnectionFairy._checkout(self)
           ~~~~~~~~~~~~~~~~~~~~~~~~~~^^^^^^
  File "/usr/local/lib/python3.13/site-packages/sqlalchemy/pool/base.py", line 1264, in _checkout
    fairy = _ConnectionRecord.checkout(pool)
  File "/usr/local/lib/python3.13/site-packages/sqlalchemy/pool/base.py", line 713, in checkout
    rec = pool._do_get()
  File "/usr/local/lib/python3.13/site-packages/sqlalchemy/pool/impl.py", line 179, in _do_get
    with util.safe_reraise():
         ~~~~~~~~~~~~~~~~~^^
  File "/usr/local/lib/python3.13/site-packages/sqlalchemy/util/langhelpers.py", line 146, in __exit__
    raise exc_value.with_traceback(exc_tb)
  File "/usr/local/lib/python3.13/site-packages/sqlalchemy/pool/impl.py", line 177, in _do_get
    return self._create_connection()
           ~~~~~~~~~~~~~~~~~~~~~~~^^
  File "/usr/local/lib/python3.13/site-packages/sqlalchemy/pool/base.py", line 390, in _create_connection
    return _ConnectionRecord(self)
  File "/usr/local/lib/python3.13/site-packages/sqlalchemy/pool/base.py", line 675, in __init__
    self.__connect()
    ~~~~~~~~~~~~~~^^
  File "/usr/local/lib/python3.13/site-packages/sqlalchemy/pool/base.py", line 901, in __connect
    with util.safe_reraise():
         ~~~~~~~~~~~~~~~~~^^
  File "/usr/local/lib/python3.13/site-packages/sqlalchemy/util/langhelpers.py", line 146, in __exit__
    raise exc_value.with_traceback(exc_tb)
  File "/usr/local/lib/python3.13/site-packages/sqlalchemy/pool/base.py", line 897, in __connect
    self.dbapi_connection = connection = pool._invoke_creator(self)
                                         ~~~~~~~~~~~~~~~~~~~~^^^^^^
  File "/usr/local/lib/python3.13/site-packages/sqlalchemy/engine/create.py", line 646, in connect
    return dialect.connect(*cargs, **cparams)
           ~~~~~~~~~~~~~~~^^^^^^^^^^^^^^^^^^^
  File "/usr/local/lib/python3.13/site-packages/sqlalchemy/engine/default.py", line 625, in connect
    return self.loaded_dbapi.connect(*cargs, **cparams)  # type: ignore[no-any-return]  # NOQA: E501
           ~~~~~~~~~~~~~~~~~~~~~~~~~^^^^^^^^^^^^^^^^^^^
  File "/usr/local/lib/python3.13/site-packages/MySQLdb/__init__.py", line 121, in Connect
    return Connection(*args, **kwargs)
  File "/usr/local/lib/python3.13/site-packages/MySQLdb/connections.py", line 200, in __init__
    super().__init__(*args, **kwargs2)
    ~~~~~~~~~~~~~~~~^^^^^^^^^^^^^^^^^^
MySQLdb.OperationalError: (2005, "Unknown server host 'mariadb' (-2)")

The above exception was the direct cause of the following exception:

Traceback (most recent call last):
  File "/usr/src/homeassistant/homeassistant/components/recorder/core.py", line 927, in _setup_recorder
    self._setup_connection()
    ~~~~~~~~~~~~~~~~~~~~~~^^
  File "/usr/src/homeassistant/homeassistant/components/recorder/core.py", line 1448, in _setup_connection
    migration.pre_migrate_schema(self.engine)
    ~~~~~~~~~~~~~~~~~~~~~~~~~~~~^^^^^^^^^^^^^
  File "/usr/src/homeassistant/homeassistant/components/recorder/migration.py", line 331, in pre_migrate_schema
    inspector = sqlalchemy.inspect(engine)
  File "/usr/local/lib/python3.13/site-packages/sqlalchemy/inspection.py", line 140, in inspect
    ret = reg(subject)
  File "/usr/local/lib/python3.13/site-packages/sqlalchemy/engine/reflection.py", line 313, in _engine_insp
    return Inspector._construct(Inspector._init_engine, bind)
           ~~~~~~~~~~~~~~~~~~~~^^^^^^^^^^^^^^^^^^^^^^^^^^^^^^
  File "/usr/local/lib/python3.13/site-packages/sqlalchemy/engine/reflection.py", line 246, in _construct
    init(self, bind)
    ~~~~^^^^^^^^^^^^
  File "/usr/local/lib/python3.13/site-packages/sqlalchemy/engine/reflection.py", line 257, in _init_engine
    engine.connect().close()
    ~~~~~~~~~~~~~~^^
  File "/usr/local/lib/python3.13/site-packages/sqlalchemy/engine/base.py", line 3274, in connect
    return self._connection_cls(self)
           ~~~~~~~~~~~~~~~~~~~~^^^^^^
  File "/usr/local/lib/python3.13/site-packages/sqlalchemy/engine/base.py", line 148, in __init__
    Connection._handle_dbapi_exception_noconnection(
    ~~~~~~~~~~~~~~~~~~~~~~~~~~~~~~~~~~~~~~~~~~~~~~~^
        err, dialect, engine
        ^^^^^^^^^^^^^^^^^^^^
    )
    ^
  File "/usr/local/lib/python3.13/site-packages/sqlalchemy/engine/base.py", line 2439, in _handle_dbapi_exception_noconnection
    raise sqlalchemy_exception.with_traceback(exc_info[2]) from e
  File "/usr/local/lib/python3.13/site-packages/sqlalchemy/engine/base.py", line 146, in __init__
    self._dbapi_connection = engine.raw_connection()
                             ~~~~~~~~~~~~~~~~~~~~~^^
  File "/usr/local/lib/python3.13/site-packages/sqlalchemy/engine/base.py", line 3298, in raw_connection
    return self.pool.connect()
           ~~~~~~~~~~~~~~~~~^^
  File "/usr/local/lib/python3.13/site-packages/sqlalchemy/pool/base.py", line 449, in connect
    return _ConnectionFairy._checkout(self)
           ~~~~~~~~~~~~~~~~~~~~~~~~~~^^^^^^
  File "/usr/local/lib/python3.13/site-packages/sqlalchemy/pool/base.py", line 1264, in _checkout
    fairy = _ConnectionRecord.checkout(pool)
  File "/usr/local/lib/python3.13/site-packages/sqlalchemy/pool/base.py", line 713, in checkout
    rec = pool._do_get()
  File "/usr/local/lib/python3.13/site-packages/sqlalchemy/pool/impl.py", line 179, in _do_get
    with util.safe_reraise():
         ~~~~~~~~~~~~~~~~~^^
  File "/usr/local/lib/python3.13/site-packages/sqlalchemy/util/langhelpers.py", line 146, in __exit__
    raise exc_value.with_traceback(exc_tb)
  File "/usr/local/lib/python3.13/site-packages/sqlalchemy/pool/impl.py", line 177, in _do_get
    return self._create_connection()
           ~~~~~~~~~~~~~~~~~~~~~~~^^
  File "/usr/local/lib/python3.13/site-packages/sqlalchemy/pool/base.py", line 390, in _create_connection
    return _ConnectionRecord(self)
  File "/usr/local/lib/python3.13/site-packages/sqlalchemy/pool/base.py", line 675, in __init__
    self.__connect()
    ~~~~~~~~~~~~~~^^
  File "/usr/local/lib/python3.13/site-packages/sqlalchemy/pool/base.py", line 901, in __connect
    with util.safe_reraise():
         ~~~~~~~~~~~~~~~~~^^
  File "/usr/local/lib/python3.13/site-packages/sqlalchemy/util/langhelpers.py", line 146, in __exit__
    raise exc_value.with_traceback(exc_tb)
  File "/usr/local/lib/python3.13/site-packages/sqlalchemy/pool/base.py", line 897, in __connect
    self.dbapi_connection = connection = pool._invoke_creator(self)
                                         ~~~~~~~~~~~~~~~~~~~~^^^^^^
  File "/usr/local/lib/python3.13/site-packages/sqlalchemy/engine/create.py", line 646, in connect
    return dialect.connect(*cargs, **cparams)
           ~~~~~~~~~~~~~~~^^^^^^^^^^^^^^^^^^^
  File "/usr/local/lib/python3.13/site-packages/sqlalchemy/engine/default.py", line 625, in connect
    return self.loaded_dbapi.connect(*cargs, **cparams)  # type: ignore[no-any-return]  # NOQA: E501
           ~~~~~~~~~~~~~~~~~~~~~~~~~^^^^^^^^^^^^^^^^^^^
  File "/usr/local/lib/python3.13/site-packages/MySQLdb/__init__.py", line 121, in Connect
    return Connection(*args, **kwargs)
  File "/usr/local/lib/python3.13/site-packages/MySQLdb/connections.py", line 200, in __init__
    super().__init__(*args, **kwargs2)
    ~~~~~~~~~~~~~~~~^^^^^^^^^^^^^^^^^^
sqlalchemy.exc.OperationalError: (MySQLdb.OperationalError) (2005, "Unknown server host 'mariadb' (-2)")
(Background on this error at: https://sqlalche.me/e/20/e3q8)
2025-06-05 22:09:16.928 ERROR (Recorder) [homeassistant.components.recorder.core] Error during connection setup: (retrying in 3 seconds)
Traceback (most recent call last):
  File "/usr/local/lib/python3.13/site-packages/sqlalchemy/engine/base.py", line 146, in __init__
    self._dbapi_connection = engine.raw_connection()
                             ~~~~~~~~~~~~~~~~~~~~~^^
  File "/usr/local/lib/python3.13/site-packages/sqlalchemy/engine/base.py", line 3298, in raw_connection
    return self.pool.connect()
           ~~~~~~~~~~~~~~~~~^^
  File "/usr/local/lib/python3.13/site-packages/sqlalchemy/pool/base.py", line 449, in connect
    return _ConnectionFairy._checkout(self)
           ~~~~~~~~~~~~~~~~~~~~~~~~~~^^^^^^
  File "/usr/local/lib/python3.13/site-packages/sqlalchemy/pool/base.py", line 1264, in _checkout
    fairy = _ConnectionRecord.checkout(pool)
  File "/usr/local/lib/python3.13/site-packages/sqlalchemy/pool/base.py", line 713, in checkout
    rec = pool._do_get()
  File "/usr/local/lib/python3.13/site-packages/sqlalchemy/pool/impl.py", line 179, in _do_get
    with util.safe_reraise():
         ~~~~~~~~~~~~~~~~~^^
  File "/usr/local/lib/python3.13/site-packages/sqlalchemy/util/langhelpers.py", line 146, in __exit__
    raise exc_value.with_traceback(exc_tb)
  File "/usr/local/lib/python3.13/site-packages/sqlalchemy/pool/impl.py", line 177, in _do_get
    return self._create_connection()
           ~~~~~~~~~~~~~~~~~~~~~~~^^
  File "/usr/local/lib/python3.13/site-packages/sqlalchemy/pool/base.py", line 390, in _create_connection
    return _ConnectionRecord(self)
  File "/usr/local/lib/python3.13/site-packages/sqlalchemy/pool/base.py", line 675, in __init__
    self.__connect()
    ~~~~~~~~~~~~~~^^
  File "/usr/local/lib/python3.13/site-packages/sqlalchemy/pool/base.py", line 901, in __connect
    with util.safe_reraise():
         ~~~~~~~~~~~~~~~~~^^
  File "/usr/local/lib/python3.13/site-packages/sqlalchemy/util/langhelpers.py", line 146, in __exit__
    raise exc_value.with_traceback(exc_tb)
  File "/usr/local/lib/python3.13/site-packages/sqlalchemy/pool/base.py", line 897, in __connect
    self.dbapi_connection = connection = pool._invoke_creator(self)
                                         ~~~~~~~~~~~~~~~~~~~~^^^^^^
  File "/usr/local/lib/python3.13/site-packages/sqlalchemy/engine/create.py", line 646, in connect
    return dialect.connect(*cargs, **cparams)
           ~~~~~~~~~~~~~~~^^^^^^^^^^^^^^^^^^^
  File "/usr/local/lib/python3.13/site-packages/sqlalchemy/engine/default.py", line 625, in connect
    return self.loaded_dbapi.connect(*cargs, **cparams)  # type: ignore[no-any-return]  # NOQA: E501
           ~~~~~~~~~~~~~~~~~~~~~~~~~^^^^^^^^^^^^^^^^^^^
  File "/usr/local/lib/python3.13/site-packages/MySQLdb/__init__.py", line 121, in Connect
    return Connection(*args, **kwargs)
  File "/usr/local/lib/python3.13/site-packages/MySQLdb/connections.py", line 200, in __init__
    super().__init__(*args, **kwargs2)
    ~~~~~~~~~~~~~~~~^^^^^^^^^^^^^^^^^^
MySQLdb.OperationalError: (2005, "Unknown server host 'mariadb' (-2)")

The above exception was the direct cause of the following exception:

Traceback (most recent call last):
  File "/usr/src/homeassistant/homeassistant/components/recorder/core.py", line 927, in _setup_recorder
    self._setup_connection()
    ~~~~~~~~~~~~~~~~~~~~~~^^
  File "/usr/src/homeassistant/homeassistant/components/recorder/core.py", line 1448, in _setup_connection
    migration.pre_migrate_schema(self.engine)
    ~~~~~~~~~~~~~~~~~~~~~~~~~~~~^^^^^^^^^^^^^
  File "/usr/src/homeassistant/homeassistant/components/recorder/migration.py", line 331, in pre_migrate_schema
    inspector = sqlalchemy.inspect(engine)
  File "/usr/local/lib/python3.13/site-packages/sqlalchemy/inspection.py", line 140, in inspect
    ret = reg(subject)
  File "/usr/local/lib/python3.13/site-packages/sqlalchemy/engine/reflection.py", line 313, in _engine_insp
    return Inspector._construct(Inspector._init_engine, bind)
           ~~~~~~~~~~~~~~~~~~~~^^^^^^^^^^^^^^^^^^^^^^^^^^^^^^
  File "/usr/local/lib/python3.13/site-packages/sqlalchemy/engine/reflection.py", line 246, in _construct
    init(self, bind)
    ~~~~^^^^^^^^^^^^
  File "/usr/local/lib/python3.13/site-packages/sqlalchemy/engine/reflection.py", line 257, in _init_engine
    engine.connect().close()
    ~~~~~~~~~~~~~~^^
  File "/usr/local/lib/python3.13/site-packages/sqlalchemy/engine/base.py", line 3274, in connect
    return self._connection_cls(self)
           ~~~~~~~~~~~~~~~~~~~~^^^^^^
  File "/usr/local/lib/python3.13/site-packages/sqlalchemy/engine/base.py", line 148, in __init__
    Connection._handle_dbapi_exception_noconnection(
    ~~~~~~~~~~~~~~~~~~~~~~~~~~~~~~~~~~~~~~~~~~~~~~~^
        err, dialect, engine
        ^^^^^^^^^^^^^^^^^^^^
    )
    ^
  File "/usr/local/lib/python3.13/site-packages/sqlalchemy/engine/base.py", line 2439, in _handle_dbapi_exception_noconnection
    raise sqlalchemy_exception.with_traceback(exc_info[2]) from e
  File "/usr/local/lib/python3.13/site-packages/sqlalchemy/engine/base.py", line 146, in __init__
    self._dbapi_connection = engine.raw_connection()
                             ~~~~~~~~~~~~~~~~~~~~~^^
  File "/usr/local/lib/python3.13/site-packages/sqlalchemy/engine/base.py", line 3298, in raw_connection
    return self.pool.connect()
           ~~~~~~~~~~~~~~~~~^^
  File "/usr/local/lib/python3.13/site-packages/sqlalchemy/pool/base.py", line 449, in connect
    return _ConnectionFairy._checkout(self)
           ~~~~~~~~~~~~~~~~~~~~~~~~~~^^^^^^
  File "/usr/local/lib/python3.13/site-packages/sqlalchemy/pool/base.py", line 1264, in _checkout
    fairy = _ConnectionRecord.checkout(pool)
  File "/usr/local/lib/python3.13/site-packages/sqlalchemy/pool/base.py", line 713, in checkout
    rec = pool._do_get()
  File "/usr/local/lib/python3.13/site-packages/sqlalchemy/pool/impl.py", line 179, in _do_get
    with util.safe_reraise():
         ~~~~~~~~~~~~~~~~~^^
  File "/usr/local/lib/python3.13/site-packages/sqlalchemy/util/langhelpers.py", line 146, in __exit__
    raise exc_value.with_traceback(exc_tb)
  File "/usr/local/lib/python3.13/site-packages/sqlalchemy/pool/impl.py", line 177, in _do_get
    return self._create_connection()
           ~~~~~~~~~~~~~~~~~~~~~~~^^
  File "/usr/local/lib/python3.13/site-packages/sqlalchemy/pool/base.py", line 390, in _create_connection
    return _ConnectionRecord(self)
  File "/usr/local/lib/python3.13/site-packages/sqlalchemy/pool/base.py", line 675, in __init__
    self.__connect()
    ~~~~~~~~~~~~~~^^
  File "/usr/local/lib/python3.13/site-packages/sqlalchemy/pool/base.py", line 901, in __connect
    with util.safe_reraise():
         ~~~~~~~~~~~~~~~~~^^
  File "/usr/local/lib/python3.13/site-packages/sqlalchemy/util/langhelpers.py", line 146, in __exit__
    raise exc_value.with_traceback(exc_tb)
  File "/usr/local/lib/python3.13/site-packages/sqlalchemy/pool/base.py", line 897, in __connect
    self.dbapi_connection = connection = pool._invoke_creator(self)
                                         ~~~~~~~~~~~~~~~~~~~~^^^^^^
  File "/usr/local/lib/python3.13/site-packages/sqlalchemy/engine/create.py", line 646, in connect
    return dialect.connect(*cargs, **cparams)
           ~~~~~~~~~~~~~~~^^^^^^^^^^^^^^^^^^^
  File "/usr/local/lib/python3.13/site-packages/sqlalchemy/engine/default.py", line 625, in connect
    return self.loaded_dbapi.connect(*cargs, **cparams)  # type: ignore[no-any-return]  # NOQA: E501
           ~~~~~~~~~~~~~~~~~~~~~~~~~^^^^^^^^^^^^^^^^^^^
  File "/usr/local/lib/python3.13/site-packages/MySQLdb/__init__.py", line 121, in Connect
    return Connection(*args, **kwargs)
  File "/usr/local/lib/python3.13/site-packages/MySQLdb/connections.py", line 200, in __init__
    super().__init__(*args, **kwargs2)
    ~~~~~~~~~~~~~~~~^^^^^^^^^^^^^^^^^^
sqlalchemy.exc.OperationalError: (MySQLdb.OperationalError) (2005, "Unknown server host 'mariadb' (-2)")
(Background on this error at: https://sqlalche.me/e/20/e3q8)
2025-06-05 22:09:19.938 ERROR (Recorder) [homeassistant.components.recorder.core] Error during connection setup: (retrying in 3 seconds)
Traceback (most recent call last):
  File "/usr/local/lib/python3.13/site-packages/sqlalchemy/engine/base.py", line 146, in __init__
    self._dbapi_connection = engine.raw_connection()
                             ~~~~~~~~~~~~~~~~~~~~~^^
  File "/usr/local/lib/python3.13/site-packages/sqlalchemy/engine/base.py", line 3298, in raw_connection
    return self.pool.connect()
           ~~~~~~~~~~~~~~~~~^^
  File "/usr/local/lib/python3.13/site-packages/sqlalchemy/pool/base.py", line 449, in connect
    return _ConnectionFairy._checkout(self)
           ~~~~~~~~~~~~~~~~~~~~~~~~~~^^^^^^
  File "/usr/local/lib/python3.13/site-packages/sqlalchemy/pool/base.py", line 1264, in _checkout
    fairy = _ConnectionRecord.checkout(pool)
  File "/usr/local/lib/python3.13/site-packages/sqlalchemy/pool/base.py", line 713, in checkout
    rec = pool._do_get()
  File "/usr/local/lib/python3.13/site-packages/sqlalchemy/pool/impl.py", line 179, in _do_get
    with util.safe_reraise():
         ~~~~~~~~~~~~~~~~~^^
  File "/usr/local/lib/python3.13/site-packages/sqlalchemy/util/langhelpers.py", line 146, in __exit__
    raise exc_value.with_traceback(exc_tb)
  File "/usr/local/lib/python3.13/site-packages/sqlalchemy/pool/impl.py", line 177, in _do_get
    return self._create_connection()
           ~~~~~~~~~~~~~~~~~~~~~~~^^
  File "/usr/local/lib/python3.13/site-packages/sqlalchemy/pool/base.py", line 390, in _create_connection
    return _ConnectionRecord(self)
  File "/usr/local/lib/python3.13/site-packages/sqlalchemy/pool/base.py", line 675, in __init__
    self.__connect()
    ~~~~~~~~~~~~~~^^
  File "/usr/local/lib/python3.13/site-packages/sqlalchemy/pool/base.py", line 901, in __connect
    with util.safe_reraise():
         ~~~~~~~~~~~~~~~~~^^
  File "/usr/local/lib/python3.13/site-packages/sqlalchemy/util/langhelpers.py", line 146, in __exit__
    raise exc_value.with_traceback(exc_tb)
  File "/usr/local/lib/python3.13/site-packages/sqlalchemy/pool/base.py", line 897, in __connect
    self.dbapi_connection = connection = pool._invoke_creator(self)
                                         ~~~~~~~~~~~~~~~~~~~~^^^^^^
  File "/usr/local/lib/python3.13/site-packages/sqlalchemy/engine/create.py", line 646, in connect
    return dialect.connect(*cargs, **cparams)
           ~~~~~~~~~~~~~~~^^^^^^^^^^^^^^^^^^^
  File "/usr/local/lib/python3.13/site-packages/sqlalchemy/engine/default.py", line 625, in connect
    return self.loaded_dbapi.connect(*cargs, **cparams)  # type: ignore[no-any-return]  # NOQA: E501
           ~~~~~~~~~~~~~~~~~~~~~~~~~^^^^^^^^^^^^^^^^^^^
  File "/usr/local/lib/python3.13/site-packages/MySQLdb/__init__.py", line 121, in Connect
    return Connection(*args, **kwargs)
  File "/usr/local/lib/python3.13/site-packages/MySQLdb/connections.py", line 200, in __init__
    super().__init__(*args, **kwargs2)
    ~~~~~~~~~~~~~~~~^^^^^^^^^^^^^^^^^^
MySQLdb.OperationalError: (2005, "Unknown server host 'mariadb' (-2)")

The above exception was the direct cause of the following exception:

Traceback (most recent call last):
  File "/usr/src/homeassistant/homeassistant/components/recorder/core.py", line 927, in _setup_recorder
    self._setup_connection()
    ~~~~~~~~~~~~~~~~~~~~~~^^
  File "/usr/src/homeassistant/homeassistant/components/recorder/core.py", line 1448, in _setup_connection
    migration.pre_migrate_schema(self.engine)
    ~~~~~~~~~~~~~~~~~~~~~~~~~~~~^^^^^^^^^^^^^
  File "/usr/src/homeassistant/homeassistant/components/recorder/migration.py", line 331, in pre_migrate_schema
    inspector = sqlalchemy.inspect(engine)
  File "/usr/local/lib/python3.13/site-packages/sqlalchemy/inspection.py", line 140, in inspect
    ret = reg(subject)
  File "/usr/local/lib/python3.13/site-packages/sqlalchemy/engine/reflection.py", line 313, in _engine_insp
    return Inspector._construct(Inspector._init_engine, bind)
           ~~~~~~~~~~~~~~~~~~~~^^^^^^^^^^^^^^^^^^^^^^^^^^^^^^
  File "/usr/local/lib/python3.13/site-packages/sqlalchemy/engine/reflection.py", line 246, in _construct
    init(self, bind)
    ~~~~^^^^^^^^^^^^
  File "/usr/local/lib/python3.13/site-packages/sqlalchemy/engine/reflection.py", line 257, in _init_engine
    engine.connect().close()
    ~~~~~~~~~~~~~~^^
  File "/usr/local/lib/python3.13/site-packages/sqlalchemy/engine/base.py", line 3274, in connect
    return self._connection_cls(self)
           ~~~~~~~~~~~~~~~~~~~~^^^^^^
  File "/usr/local/lib/python3.13/site-packages/sqlalchemy/engine/base.py", line 148, in __init__
    Connection._handle_dbapi_exception_noconnection(
    ~~~~~~~~~~~~~~~~~~~~~~~~~~~~~~~~~~~~~~~~~~~~~~~^
        err, dialect, engine
        ^^^^^^^^^^^^^^^^^^^^
    )
    ^
  File "/usr/local/lib/python3.13/site-packages/sqlalchemy/engine/base.py", line 2439, in _handle_dbapi_exception_noconnection
    raise sqlalchemy_exception.with_traceback(exc_info[2]) from e
  File "/usr/local/lib/python3.13/site-packages/sqlalchemy/engine/base.py", line 146, in __init__
    self._dbapi_connection = engine.raw_connection()
                             ~~~~~~~~~~~~~~~~~~~~~^^
  File "/usr/local/lib/python3.13/site-packages/sqlalchemy/engine/base.py", line 3298, in raw_connection
    return self.pool.connect()
           ~~~~~~~~~~~~~~~~~^^
  File "/usr/local/lib/python3.13/site-packages/sqlalchemy/pool/base.py", line 449, in connect
    return _ConnectionFairy._checkout(self)
           ~~~~~~~~~~~~~~~~~~~~~~~~~~^^^^^^
  File "/usr/local/lib/python3.13/site-packages/sqlalchemy/pool/base.py", line 1264, in _checkout
    fairy = _ConnectionRecord.checkout(pool)
  File "/usr/local/lib/python3.13/site-packages/sqlalchemy/pool/base.py", line 713, in checkout
    rec = pool._do_get()
  File "/usr/local/lib/python3.13/site-packages/sqlalchemy/pool/impl.py", line 179, in _do_get
    with util.safe_reraise():
         ~~~~~~~~~~~~~~~~~^^
  File "/usr/local/lib/python3.13/site-packages/sqlalchemy/util/langhelpers.py", line 146, in __exit__
    raise exc_value.with_traceback(exc_tb)
  File "/usr/local/lib/python3.13/site-packages/sqlalchemy/pool/impl.py", line 177, in _do_get
    return self._create_connection()
           ~~~~~~~~~~~~~~~~~~~~~~~^^
  File "/usr/local/lib/python3.13/site-packages/sqlalchemy/pool/base.py", line 390, in _create_connection
    return _ConnectionRecord(self)
  File "/usr/local/lib/python3.13/site-packages/sqlalchemy/pool/base.py", line 675, in __init__
    self.__connect()
    ~~~~~~~~~~~~~~^^
  File "/usr/local/lib/python3.13/site-packages/sqlalchemy/pool/base.py", line 901, in __connect
    with util.safe_reraise():
         ~~~~~~~~~~~~~~~~~^^
  File "/usr/local/lib/python3.13/site-packages/sqlalchemy/util/langhelpers.py", line 146, in __exit__
    raise exc_value.with_traceback(exc_tb)
  File "/usr/local/lib/python3.13/site-packages/sqlalchemy/pool/base.py", line 897, in __connect
    self.dbapi_connection = connection = pool._invoke_creator(self)
                                         ~~~~~~~~~~~~~~~~~~~~^^^^^^
  File "/usr/local/lib/python3.13/site-packages/sqlalchemy/engine/create.py", line 646, in connect
    return dialect.connect(*cargs, **cparams)
           ~~~~~~~~~~~~~~~^^^^^^^^^^^^^^^^^^^
  File "/usr/local/lib/python3.13/site-packages/sqlalchemy/engine/default.py", line 625, in connect
    return self.loaded_dbapi.connect(*cargs, **cparams)  # type: ignore[no-any-return]  # NOQA: E501
           ~~~~~~~~~~~~~~~~~~~~~~~~~^^^^^^^^^^^^^^^^^^^
  File "/usr/local/lib/python3.13/site-packages/MySQLdb/__init__.py", line 121, in Connect
    return Connection(*args, **kwargs)
  File "/usr/local/lib/python3.13/site-packages/MySQLdb/connections.py", line 200, in __init__
    super().__init__(*args, **kwargs2)
    ~~~~~~~~~~~~~~~~^^^^^^^^^^^^^^^^^^
sqlalchemy.exc.OperationalError: (MySQLdb.OperationalError) (2005, "Unknown server host 'mariadb' (-2)")
(Background on this error at: https://sqlalche.me/e/20/e3q8)
2025-06-05 22:09:19.943 ERROR (Recorder) [homeassistant.components.recorder.core] Recorder setup failed, recorder shutting down
2025-06-05 22:09:19.943 ERROR (MainThread) [homeassistant.setup] Setup failed for 'recorder': Integration failed to initialize.
2025-06-05 22:09:23.437 ERROR (MainThread) [homeassistant.setup] Unable to set up dependencies of 'history'. Setup failed for dependencies: ['recorder']
2025-06-05 22:09:23.437 ERROR (MainThread) [homeassistant.setup] Setup failed for 'history': Could not setup dependencies: recorder
2025-06-05 22:09:23.437 ERROR (MainThread) [homeassistant.setup] Unable to set up dependencies of 'energy'. Setup failed for dependencies: ['history', 'recorder']
2025-06-05 22:09:23.437 ERROR (MainThread) [homeassistant.setup] Setup failed for 'energy': Could not setup dependencies: history, recorder
2025-06-05 22:09:23.449 ERROR (MainThread) [homeassistant.setup] Unable to set up dependencies of 'logbook'. Setup failed for dependencies: ['recorder']
2025-06-05 22:09:23.449 ERROR (MainThread) [homeassistant.setup] Setup failed for 'logbook': Could not setup dependencies: recorder
2025-06-05 22:09:26.540 ERROR (SyncWorker_2) [homeassistant.components.influxdb] InfluxDB bucket is not accessible due to '(401)
Reason: Unauthorized
HTTP response headers: HTTPHeaderDict({'Content-Type': 'application/json; charset=utf-8', 'X-Influxdb-Build': 'OSS', 'X-Influxdb-Version': 'v2.7.12', 'X-Platform-Error-Code': 'unauthorized', 'Date': 'Thu, 05 Jun 2025 22:09:26 GMT', 'Content-Length': '55'})
HTTP response body: {"code":"unauthorized","message":"unauthorized access"}
'. Please check that the bucket, org and token are correct and that the token has the correct permissions set. Retrying in 60 seconds.
2025-06-05 22:09:26.744 ERROR (MainThread) [homeassistant.setup] Unable to set up dependencies of 'default_config'. Setup failed for dependencies: ['energy', 'history', 'logbook']
2025-06-05 22:09:26.744 ERROR (MainThread) [homeassistant.setup] Setup failed for 'default_config': Could not setup dependencies: energy, history, logbook
